File: data/raw_data/xps/20171212_Gr-NH2/20171130_Gr-NH2.vms
VAMAS Surface Chemical Analysis Standard Data Transfer Format 1988 May 4
Not Specified
Kratos Axis
Not Specified
/C=/data/KristianBB/20171211/Emil.dset
12
Casa Info Follows
5
C 1s
C 1s
F 1s
F 1s
N 1s
N 1s
O 1s
O 1s
S 2p
S 2p
MAP
REGULAR
3
6
32768
32768
1
Etch Time
s
0
0
0
0
12
Survey/2
Not Specified
2017
12
11
12
50
42
0
15
Casa Info Follows
1
Calib M = 280.836 A = 284.5 BE ADD
1
annot regions Display 0.05 0.05 RGB(0,0,0) Font(12,18,0,0,Times New Roman)

4
CASA region (*O 1s*) (*Shirley*) 946.22596 960.276 0.78 1 0 0 299 542 275 9.3 (*O 1s*) 15.9994
CASA region (*C 1s*) (*Shirley*) 1189.5918 1207.276 0.278 1 0 0 299 542 275 9.3 (*C 1s*) 12.011
CASA region (*N 1s*) (*Shirley*) 1083.9344 1089.6329 0.477 1 0 0 299 542 275 9.3 (*N 1s*) 14.0067
CASA region (*S 2p*) (*Shirley*) 1314.9172 1320.8173 0.668 1 0 0 299 542 275 9.3 (*S 2p*) 32.0648
0
   XPS     Spectrum    Lens Mode:Hybrid   Resolution:Pass energy 160   Iris(Aper):slot(Slot)
   Acqn. Time(s): 540        Sweeps: 2        Anode:Mono(Al (Mono))(150 W)   Step(meV): 500.0
   Dwell Time(ms): 100        Charge Neutraliser :On   Acquired On :17/12/11 12:50:42
XPS
-4
-1
0
Mono(Al (Mono))
1486.69
150
1e+037
1e+037
6000
6000
1e+037
1e+037
FAT
160
1e+037
-4.803
0
1e+037
1e+037
1e+037
1e+037
Wide
None
-1
Kinetic Energy
eV
136.69
0.5
2
Intensity
d
Transmission
d
pulse counting
0.1
1e+037
140
10162
10078
10162
9887
10119
10092
10129
10043
10016
10063
10103
10274
9958
10206
9948
10102
10109
10026
9962
10143
10028
9978
10175
10233
10012
10229
10064
10169
10075
10086
10212
10140
10036
9959
10083
10103
10120
10101
10103
10215
10310
10197
10060
10035
10222
10391
10448
10324
10328
10389
10380
10508
10121
10277
10302
10462
10441
10484
10558
10471
10485
10383
10515
10527
10492
10645
10679
10513
10773
10735
10890
10894
10995
11158
11138
11095
10975
11042
11109
11010
11022
11096
11306
11122
11292
11362
11303
11422
11423
11454
11259
11403
11437
11419
11585
11505
11588
11759
11731
11734
11776
11845
11926
11971
12093
12158
12343
12471
12344
12206
12383
12507
12470
12290
12360
12338
12341
12266
12285
12436
12496
13068
13278
13272
13394
13521
13613
13782
13664
13808
13733
13595
13382
13381
13189
12834
12603
12127
11726
11206
10751
10218
9773
9255
8584
8187
7871
7557
7211
7112
6930
6803
6641
6821
6689
6498
6660
6608
6668
6586
6618
6587
6792
6682
6704
6682
6630
6670
6784
6739
6737
6699
6702
6706
6766
6698
6731
6931
6869
6811
6773
6799
6766
6881
6873
6876
6807
6826
6850
6960
6792
6836
6994
6871
6954
6888
6810
6846
6950
6918
6823
6940
6908
7015
6990
7016
6938
6998
7042
7098
6984
7097
7058
6949
7105
7125
7134
7162
7063
7134
7125
7021
7167
7043
7209
7198
7103
7110
7247
7320
7312
7247
7322
7426
7189
7234
7303
7433
7364
7260
7344
7259
7413
7291
7359
7353
7342
7419
7491
7531
7495
7513
7379
7274
7421
7411
7424
7542
7305
7407
7310
7395
7325
7372
7305
7549
7374
7504
7443
7490
7504
7588
7529
7340
7561
7560
7600
7667
7630
7553
7711
7495
7509
7664
7673
7603
7583
7821
7713
7738
7669
7754
7652
7750
7677
7806
7821
7664
7890
7901
7805
7748
7898
7808
7880
7848
7825
7851
7988
7996
8007
7856
7903
7966
8069
8019
8075
8031
7960
8071
8103
8166
8185
8135
8195
8151
8072
8237
8149
8445
8242
8264
8321
8242
8413
8352
8594
8367
8488
8427
8564
8489
8373
8465
8378
8621
8537
8757
8691
8622
8750
8818
9004
8963
9048
9060
9027
8757
8848
8986
8768
8595
8557
8420
8515
8369
8420
8520
8367
8407
8748
8712
9145
9122
9539
9545
9910
10040
9901
9981
9696
9548
9229
9243
8806
8487
8153
7807
7507
7351
7313
7086
7090
7118
7090
7002
7026
7142
7044
6992
7092
6955
7129
7015
7130
7021
7023
6923
7161
7030
7144
7161
7225
6994
7118
7185
7060
7158
7319
7180
7206
7183
7208
7126
7325
7128
7158
7295
7293
7242
7258
7286
7299
7294
7310
7343
7299
7149
7196
7365
7369
7438
7313
7126
7349
7494
7349
7353
7444
7400
7420
7379
7369
7330
7439
7358
7372
7483
7331
7395
7512
7562
7479
7332
7420
7457
7582
7706
7552
7569
7409
7592
7533
7648
7669
7517
7501
7561
7668
7686
7601
7560
7556
7642
7616
7727
7626
7598
7700
7739
7805
7631
7592
7617
7693
7690
7853
7671
7782
7628
7637
7672
7768
7985
7744
7783
7618
7728
7769
7709
7802
7810
7889
7770
7697
7829
7737
7910
7773
7898
7876
7898
8008
7987
7898
8015
7862
7843
7954
7921
7976
7817
8022
7978
8010
7902
8017
7999
7956
7938
8035
7896
8049
7934
8056
8063
8102
8072
8106
8146
8048
8068
8033
8074
8145
8102
8165
8140
8178
8026
8007
8240
8034
8037
8492
8166
8161
8199
8205
8074
8217
8178
8159
8076
8297
8114
8229
8342
8308
8312
8313
8421
8183
8332
8336
8343
8291
8225
8350
8334
8448
8427
8436
8293
8525
8458
8404
8419
8370
8548
8477
8477
8518
8434
8579
8450
8435
8555
8355
8490
8423
8438
8366
8638
8780
8512
8488
8752
8568
8615
8539
8536
8728
8620
8788
8737
8567
8718
8683
8757
8845
8656
8812
8803
8617
8734
8852
8790
8901
8741
8688
8844
8855
8739
8815
8732
8785
8793
8835
8810
8898
8719
8915
8717
8815
8867
8925
8863
8761
9058
8998
8867
8972
8913
8839
9001
9069
9108
9059
8962
9025
8980
9143
9043
8896
9258
9026
9056
9062
9095
8963
9132
9192
9097
8952
9120
9119
9131
9081
9254
9047
9298
9092
9114
9198
9102
9209
9241
9233
9150
9223
9395
9426
9359
9401
9333
9273
9112
9278
9288
9217
9425
9272
9387
9303
9315
9215
9423
9290
9331
9403
9560
9418
9443
9378
9390
9460
9495
9413
9458
9500
9490
9477
9568
9423
9382
9514
9412
9649
9544
9749
9536
9696
9820
9598
9661
9599
9689
9817
9624
9669
9512
9630
9784
9803
9753
9732
9878
9744
9923
9804
9859
9800
9845
9976
9725
9859
9786
10075
9972
9909
10057
9816
9847
9931
10058
9951
9843
9828
9924
9881
9851
9982
9850
10037
9970
10135
10072
10030
10106
10198
10139
10346
10316
10389
10429
10449
10247
10332
10190
10114
10046
10019
9940
9874
9657
9774
9595
9596
9407
9364
9202
9372
9314
9427
9438
9766
9944
10466
12350
16575
21160
19580
14418
10153
8635
8480
8182
8344
8121
8446
8218
8177
8383
8439
8369
8465
8319
8334
8249
8360
8450
8317
8295
8475
8449
8358
8554
8418
8403
8325
8398
8501
8438
8465
8555
8519
8352
8469
8613
8534
8516
8569
8536
8507
8802
8529
8533
8617
8719
8615
8620
8731
8649
8757
8874
8776
8623
8711
8755
8591
8612
8719
8741
8873
8767
8807
8783
8845
8875
8834
8851
8821
8878
8863
8978
8875
8929
8871
9147
8969
9038
9068
9053
9116
9041
9109
9038
9160
9104
9233
9013
9035
9204
9099
9171
9204
9206
9237
9171
9253
9064
9123
9209
9132
9291
9254
9308
9246
9155
9332
9268
9422
9572
9242
9322
9279
9264
9427
9370
9328
9424
9475
9383
9425
9558
9480
9580
9637
9639
9601
9685
9714
10283
10657
10330
9662
9622
9668
9655
9484
9515
9436
9687
9710
9565
9832
9737
9613
9732
9636
9735
9668
9832
9751
9941
10043
9950
9955
10000
10000
9874
9875
9958
9925
10035
9837
9979
10021
10189
10063
9992
10036
10050
10220
10230
10233
10221
10177
10032
10246
10230
10359
10389
10656
10487
10509
10504
10589
10629
10476
10591
10556
10414
10318
10394
10518
10270
10279
10252
10100
10051
10026
10245
10104
10204
10212
10317
10456
10576
10896
11000
11133
11279
11378
11565
11601
11867
11863
11904
11843
12127
11769
11386
11315
10780
10224
9775
9092
8562
8080
7621
6852
6584
6288
6130
5782
5866
6095
6578
7055
7590
8687
9595
10436
12116
15046
20227
33854
65128
41284
6834
1908
1311
1029
838
749
663
628
560
573
555
505
544
522
521
568
542
531
567
553
524
501
515
542
508
517
508
531
509
522
524
548
493
493
511
511
527
542
511
507
546
514
524
514
498
547
529
498
547
543
532
559
572
527
491
548
502
483
493
511
488
509
472
502
514
489
498
481
488
490
509
503
511
486
510
483
464
528
516
505
516
509
522
528
514
514
494
491
508
535
531
569
532
523
462
521
470
517
472
497
452
513
467
475
445
471
507
521
451
484
479
470
521
607
707
609
554
487
533
478
489
534
506
531
517
478
466
493
513
509
531
517
486
500
478
477
488
529
468
472
518
479
512
494
501
491
498
500
519
476
490
500
503
547
478
506
460
479
493
483
500
516
529
498
487
504
477
499
504
482
526
515
541
535
514
506
530
510
488
514
547
546
522
514
517
488
537
506
505
556
486
523
542
540
541
533
500
526
557
508
494
536
559
525
513
524
560
499
571
564
538
555
528
520
514
592
556
529
568
544
519
493
560
571
544
590
560
567
582
602
583
621
585
586
594
642
593
635
653
606
631
583
546
560
533
508
515
494
486
511
502
505
548
601
630
673
714
736
718
665
680
719
810
866
879
875
883
800
775
719
621
576
529
460
434
380
292
267
184
140
29.504
C 1s/3
Not Specified
2017
12
11
13
2
50
0
9
Casa Info Follows
1
Calib M = 280.836 A = 284.5 BE ADD
0
0
0
   XPS     Spectrum    Lens Mode:Hybrid   Resolution:Pass energy 20    Iris(Aper):slot(Slot)
   Acqn. Time(s): 261        Sweeps: 4        Anode:Mono(Al (Mono))(150 W)   Step(meV): 100.0
   Dwell Time(ms): 250        Charge Neutraliser :On   Acquired On :17/12/11 13:02:50
XPS
-4
-1
0
Mono(Al (Mono))
1486.69
150
1e+037
1e+037
6000
6000
1e+037
1e+037
FAT
20
1e+037
-4.803
0
1e+037
1e+037
1e+037
1e+037
C
1s
-1
Kinetic Energy
eV
1186.69
0.1
2
Intensity
d
Transmission
d
pulse counting
0.25
4
0
1e+037
1e+037
1e+037
0
522
140
35402
1.1574
1.16426
1857
1.16426
1821
1.16422
1755
1.16418
1774
1.16414
1832
1.1641
1738
1.16406
1706
1.16402
1719
1.16398
1696
1.16393
1732
1.16389
1674
1.16385
1676
1.16381
1666
1.16377
1611
1.16373
1612
1.16369
1600
1.16365
1625
1.16361
1556
1.16357
1585
1.16352
1510
1.16348
1474
1.16344
1504
1.1634
1541
1.16336
1483
1.16332
1533
1.16328
1538
1.16324
1498
1.1632
1482
1.16315
1427
1.16311
1501
1.16307
1355
1.16303
1416
1.16299
1423
1.16295
1465
1.16292
1399
1.1629
1394
1.16287
1458
1.16285
1405
1.16282
1374
1.1628
1381
1.16278
1330
1.16275
1352
1.16273
1384
1.1627
1334
1.16268
1292
1.16265
1374
1.16263
1339
1.16261
1317
1.16258
1338
1.16256
1373
1.16253
1372
1.16251
1296
1.16248
1356
1.16246
1336
1.16244
1300
1.16241
1325
1.16239
1316
1.16236
1276
1.16234
1243
1.16231
1254
1.16229
1310
1.16226
1261
1.16224
1244
1.16222
1315
1.16219
1315
1.16217
1261
1.16214
1283
1.16212
1260
1.16209
1239
1.16207
1291
1.16205
1283
1.16202
1274
1.162
1239
1.16197
1254
1.16195
1240
1.16192
1253
1.1619
1282
1.16188
1366
1.16185
1354
1.16183
1359
1.1618
1345
1.16178
1348
1.16175
1355
1.16173
1371
1.16171
1403
1.16168
1401
1.16166
1451
1.16163
1383
1.16161
1423
1.16158
1445
1.16156
1490
1.16153
1431
1.16151
1436
1.16149
1425
1.16146
1470
1.16144
1451
1.16141
1451
1.16139
1431
1.16136
1433
1.16134
1537
1.16132
1505
1.16129
1448
1.16127
1524
1.16124
1555
1.16122
1454
1.16119
1432
1.16117
1549
1.16115
1565
1.16112
1573
1.1611
1560
1.16107
1566
1.16105
1654
1.16102
1712
1.161
1687
1.16097
1734
1.16095
1791
1.16093
1820
1.1609
1837
1.16088
1736
1.16085
1824
1.16083
1843
1.1608
1900
1.16078
1910
1.16076
1934
1.16073
2028
1.16071
2008
1.16068
1945
1.16066
1964
1.16063
1950
1.16061
1974
1.16059
1953
1.16056
2020
1.16054
1971
1.16051
1945
1.16049
1976
1.16046
1995
1.16044
1989
1.16042
1940
1.16039
1946
1.16037
2042
1.16034
2017
1.16032
2012
1.16029
2053
1.16027
2040
1.16024
2098
1.16022
2103
1.1602
2234
1.16017
2232
1.16015
2321
1.16012
2342
1.1601
2407
1.16007
2428
1.16005
2492
1.16003
2564
1.16
2573
1.15998
2684
1.15995
2690
1.15993
2738
1.1599
2857
1.15988
2830
1.15986
3001
1.15983
3104
1.15981
3267
1.15978
3351
1.15976
3523
1.15973
3670
1.15971
3804
1.15969
3966
1.15966
4230
1.15964
4381
1.15961
4296
1.15959
4351
1.15956
4424
1.15954
4471
1.15951
4541
1.15949
4571
1.15947
4620
1.15944
4713
1.15942
4916
1.15939
5384
1.15937
5655
1.15934
6074
1.15932
6757
1.1593
7670
1.15927
8766
1.15925
10363
1.15922
12611
1.1592
15816
1.15917
20013
1.15915
25418
1.15913
30973
1.1591
35402
1.15908
35288
1.15905
30839
1.15903
22899
1.159
15443
1.15898
9896
1.15895
6152
1.15893
4019
1.15891
2707
1.15888
1898
1.15886
1353
1.15883
1073
1.15881
819
1.15878
671
1.15876
536
1.15874
489
1.15871
433
1.15869
365
1.15866
372
1.15864
361
1.15861
354
1.15859
324
1.15857
302
1.15854
315
1.15852
260
1.15849
275
1.15847
243
1.15844
242
1.15842
224
1.1584
212
1.15837
197
1.15835
238
1.15832
220
1.1583
211
1.15827
194
1.15825
182
1.15822
182
1.1582
193
1.15818
207
1.15815
175
1.15813
147
1.1581
183
1.15808
178
1.15805
197
1.15803
160
1.15801
187
1.15798
177
1.15796
187
1.15793
172
1.15791
153
1.15788
173
1.15786
167
1.15784
166
1.15781
145
1.15779
162
1.15776
147
1.15774
169
1.15771
153
1.15769
152
1.15767
157
1.15764
171
1.15762
147
1.15759
142
1.15757
181
1.15754
143
1.15752
152
1.15749
140
1.15747
167
1.15745
156
1.15742
155
1.1574
N 1s/4
Not Specified
2017
12
11
13
2
50
0
9
Casa Info Follows
1
Calib M = 280.836 A = 284.5 BE ADD
0
0
0
   XPS     Spectrum    Lens Mode:Hybrid   Resolution:Pass energy 20    Iris(Aper):slot(Slot)
   Acqn. Time(s): 241        Sweeps: 4        Anode:Mono(Al (Mono))(150 W)   Step(meV): 100.0
   Dwell Time(ms): 298        Charge Neutraliser :On   Acquired On :17/12/11 13:02:50
XPS
-4
-1
0
Mono(Al (Mono))
1486.69
150
1e+037
1e+037
6000
6000
1e+037
1e+037
FAT
20
1e+037
-4.803
0
1e+037
1e+037
1e+037
1e+037
N
1s
-1
Kinetic Energy
eV
1076.69
0.1
2
Intensity
d
Transmission
d
pulse counting
0.2985
4
0
1e+037
1e+037
1e+037
0
404
2518
3160
1.20216
1.21679
2689
1.21679
2583
1.21671
2653
1.21664
2574
1.21657
2584
1.2165
2626
1.21642
2598
1.21635
2641
1.21628
2598
1.21621
2603
1.21613
2683
1.21606
2601
1.21599
2630
1.21591
2661
1.21584
2598
1.21577
2603
1.2157
2641
1.21562
2679
1.21555
2603
1.21548
2685
1.2154
2657
1.21533
2583
1.21526
2594
1.21519
2670
1.21511
2781
1.21504
2589
1.21497
2638
1.2149
2691
1.21482
2642
1.21475
2639
1.21468
2576
1.2146
2586
1.21453
2606
1.21446
2686
1.21439
2613
1.21431
2599
1.21424
2625
1.21417
2621
1.2141
2644
1.21402
2658
1.21395
2674
1.21388
2643
1.2138
2634
1.21373
2655
1.21366
2668
1.21359
2584
1.21351
2626
1.21344
2661
1.21337
2635
1.21329
2572
1.21322
2626
1.21315
2609
1.21308
2588
1.213
2652
1.21293
2642
1.21286
2660
1.21279
2635
1.21271
2607
1.21264
2643
1.21257
2614
1.21249
2572
1.21242
2670
1.21235
2611
1.21228
2603
1.2122
2622
1.21213
2643
1.21206
2658
1.21198
2616
1.21191
2720
1.21184
2595
1.21177
2656
1.21169
2609
1.21162
2566
1.21155
2659
1.21148
2718
1.2114
2682
1.21133
2681
1.21126
2663
1.21118
2602
1.21111
2548
1.21104
2653
1.21097
2628
1.21089
2592
1.21082
2588
1.21075
2665
1.21068
2646
1.2106
2643
1.21053
2589
1.21046
2539
1.21038
2607
1.21031
2597
1.21024
2664
1.21017
2656
1.21009
2664
1.21002
2669
1.20995
2618
1.20987
2620
1.2098
2624
1.20973
2618
1.20966
2609
1.20958
2592
1.20951
2611
1.20944
2681
1.20937
2653
1.20929
2656
1.20922
2659
1.20915
2673
1.20907
2667
1.209
2711
1.20893
2731
1.20886
2677
1.20878
2658
1.20871
2667
1.20864
2706
1.20856
2604
1.20849
2715
1.20842
2749
1.20835
2763
1.20827
2756
1.2082
2775
1.20813
2703
1.20806
2719
1.20798
2795
1.20791
2801
1.20784
2810
1.20776
2789
1.20769
2809
1.20762
2829
1.20755
2808
1.20747
2807
1.2074
2769
1.20733
2893
1.20726
3016
1.20718
2976
1.20711
2959
1.20704
2987
1.20696
3006
1.20689
3099
1.20682
3057
1.20675
3111
1.20667
3160
1.2066
3082
1.20653
3076
1.20645
2903
1.20638
2936
1.20631
2987
1.20624
2895
1.20616
2792
1.20609
2814
1.20602
2764
1.20595
2703
1.20587
2724
1.2058
2677
1.20573
2698
1.20565
2705
1.20558
2681
1.20551
2674
1.20544
2631
1.20536
2657
1.20529
2627
1.20522
2623
1.20514
2671
1.20507
2637
1.205
2615
1.20493
2692
1.20485
2665
1.20478
2740
1.20471
2594
1.20464
2597
1.20456
2649
1.20449
2626
1.20442
2620
1.20434
2633
1.20427
2626
1.2042
2673
1.20413
2598
1.20405
2657
1.20398
2597
1.20391
2651
1.20384
2634
1.20376
2565
1.20369
2594
1.20362
2666
1.20354
2579
1.20347
2685
1.2034
2627
1.20333
2661
1.20325
2651
1.20318
2567
1.20311
2554
1.20303
2700
1.20296
2518
1.20289
2653
1.20282
2665
1.20274
2654
1.20267
2653
1.2026
2538
1.20253
2590
1.20245
2690
1.20238
2707
1.20231
2701
1.20223
2634
1.20216
Survey/7
Not Specified
2017
12
11
13
13
15
0
15
Casa Info Follows
1
Calib M = 280.699 A = 284.5 BE ADD
1
annot regions Display 0.05 0.05 RGB(0,0,0) Font(12,18,0,0,Times New Roman)

4
CASA region (*O 1s*) (*Shirley*) 946.73224 959.639 0.78 1 0 0 299 542 275 9.3 (*O 1s*) 15.9994
CASA region (*C 1s*) (*Shirley*) 1189.6953 1207.139 0.278 1 0 0 299 542 275 9.3 (*C 1s*) 12.011
CASA region (*N 1s*) (*Shirley*) 1079.139 1089.6038 0.477 1 0 0 299 542 275 9.3 (*N 1s*) 14.0067
CASA region (*S 2p*) (*Shirley*) 1315.3652 1320.0126 0.668 1 0 0 299 542 275 9.3 (*S 2p*) 32.0648
0
   XPS     Spectrum    Lens Mode:Hybrid   Resolution:Pass energy 160   Iris(Aper):slot(Slot)
   Acqn. Time(s): 540        Sweeps: 2        Anode:Mono(Al (Mono))(150 W)   Step(meV): 500.0
   Dwell Time(ms): 100        Charge Neutraliser :On   Acquired On :17/12/11 13:13:15
XPS
0
0
0
Mono(Al (Mono))
1486.69
150
1e+037
1e+037
6000
6000
1e+037
1e+037
FAT
160
1e+037
-4.803
0
1e+037
1e+037
1e+037
1e+037
Wide
None
-1
Kinetic Energy
eV
136.69
0.5
2
Intensity
d
Transmission
d
pulse counting
0.1
1e+037
129
9737
9635
9580
9602
9652
9557
9534
9599
9509
9618
9515
9567
9573
9607
9603
9671
9763
9616
9538
9547
9587
9502
9425
9522
9653
9676
9763
9514
9590
9653
9579
9608
9572
9535
9546
9645
9477
9532
9416
9607
9440
9662
9619
9729
9830
10025
9917
9997
9920
9972
10043
10029
10009
9998
9796
9960
10119
9980
9962
10026
10103
10117
10146
10134
10187
10182
10345
10268
10280
10345
10162
10364
10258
10269
10556
10418
10336
10466
10310
10534
10508
10408
10614
10583
10811
10753
10832
10881
10796
10754
10930
10817
10856
10829
10932
10932
10986
11002
10976
11245
11292
11322
11333
11322
11436
11529
11537
11735
11783
11772
11720
11935
11703
11684
11699
11854
11530
11739
11841
12045
12146
12477
12526
12603
12875
12744
13080
12932
12949
12976
12971
12738
12797
12677
12205
11964
11770
11419
11161
10465
9955
9714
9254
8730
8203
8005
7617
7337
7095
6805
6691
6722
6540
6426
6613
6451
6517
6444
6341
6533
6558
6475
6477
6449
6505
6497
6683
6402
6530
6525
6570
6521
6467
6631
6561
6530
6679
6521
6631
6595
6624
6673
6744
6562
6705
6754
6645
6697
6791
6792
6803
6673
6732
6729
6674
6766
6864
6716
6780
6796
6671
6823
6785
6753
6906
6806
6836
6799
6905
6952
6886
6852
6819
6841
6824
6992
6784
6928
6873
6914
6957
6969
7045
6938
7044
7024
7064
7025
6952
7088
7116
7138
7200
7112
7156
7141
7165
7059
7196
7082
7166
7110
7206
7150
7161
7296
7225
7370
7336
7272
7416
7362
7253
7183
7202
7156
7057
7066
7109
7031
7145
7240
7184
7162
7263
7220
7303
7367
7240
7430
7208
7257
7273
7216
7266
7122
7373
7327
7373
7424
7392
7480
7503
7497
7362
7459
7406
7301
7479
7552
7446
7413
7404
7368
7506
7522
7558
7591
7567
7503
7554
7586
7417
7619
7705
7652
7642
7763
7748
7794
7775
7733
7538
7826
7667
7937
7912
7789
7737
7697
7778
7765
7949
7865
7868
7902
7985
7839
8080
8052
8045
7977
8086
7924
8133
8168
8234
8078
8141
8229
8149
8143
8213
8345
8160
8252
8404
8318
8476
8447
8528
8771
8654
8839
8702
8782
8779
8869
8607
8496
8463
8277
8329
8138
8256
8126
8121
7983
8203
8301
8312
8477
8481
8917
9056
9268
9588
9612
9657
9590
9464
9186
8937
8628
8452
8130
7860
7586
7341
7216
6915
6844
6908
6701
6876
6711
6742
6732
6750
6687
6776
6739
6690
6854
6788
6728
6834
6854
6803
6814
6715
6831
6760
6731
6771
6904
6859
6914
6906
6851
6799
6922
6854
6871
6929
6892
6856
6895
6855
6805
6984
6925
6960
6922
6885
6923
6887
6985
7165
7106
6982
6948
7014
6992
7019
6971
7164
7153
7115
7078
7031
7023
7062
7027
7000
7045
7051
7011
7099
7172
7167
7116
7208
7340
7065
7249
7023
7114
7265
7142
7012
7261
7311
7137
7220
7123
7184
7264
7229
7293
7296
7256
7244
7352
7371
7312
7260
7202
7203
7312
7429
7450
7336
7439
7321
7406
7298
7483
7487
7371
7433
7410
7419
7423
7373
7420
7408
7495
7495
7430
7511
7394
7467
7485
7547
7522
7468
7531
7543
7540
7592
7645
7454
7605
7680
7756
7584
7692
7576
7608
7581
7731
7694
7560
7604
7679
7685
7748
7631
7570
7693
7669
7707
7703
7675
7627
7674
7722
7652
7707
7737
7744
7860
7825
7740
7749
7874
7824
7772
7727
7964
7809
7882
7810
7638
7804
7833
7756
7806
7935
7917
7902
7801
7958
7968
7736
7985
7889
7898
7974
7950
7939
7985
8070
7898
7953
8021
8198
7867
8082
8118
8118
8046
8162
7899
8025
8116
8052
8323
8165
8122
8021
8056
8067
8076
8132
8198
8250
8246
8198
8134
8228
8248
8295
8228
8230
8252
8146
8256
8210
8273
8228
8125
8298
8284
8288
8208
8377
8406
8331
8391
8342
8428
8398
8201
8386
8405
8417
8408
8477
8478
8403
8424
8326
8498
8405
8365
8415
8331
8517
8561
8446
8472
8423
8624
8339
8571
8547
8638
8527
8616
8557
8572
8531
8529
8481
8575
8653
8656
8636
8569
8651
8611
8633
8560
8687
8740
8700
8790
8650
8669
8666
8740
8662
8783
8695
8725
8742
8835
8805
8819
8760
8777
8655
8839
8580
8783
8798
8754
8834
8856
8818
8981
8928
9019
8920
8976
8895
8917
9006
8866
8899
8770
9087
9053
9049
8865
8986
9117
9081
9144
8975
9120
8995
9058
9090
8961
8886
9128
9122
9008
9119
9117
9188
9245
9078
9234
9040
9188
9347
9184
9176
9212
9357
9157
9365
9126
9163
9353
9193
9266
9194
9475
9319
9251
9372
9269
9267
9371
9283
9415
9369
9420
9401
9320
9373
9426
9578
9545
9404
9506
9595
9502
9476
9264
9405
9550
9645
9417
9459
9493
9571
9555
9675
9547
9388
9514
9563
9748
9642
9635
9707
9677
9895
10047
10118
9984
9993
9939
9809
9643
9705
9441
9467
9279
9277
9107
8978
9151
8830
8849
8758
8743
8786
8811
8973
9217
9647
10473
12061
15890
19317
18236
13724
9704
8196
8070
7871
7743
7884
7796
7753
7693
7739
7755
7859
7854
7856
7731
7748
7750
7903
7859
7924
7871
7979
7844
8117
7741
8021
7849
7970
8019
7777
7870
8010
7983
8054
8014
8017
7856
7929
8107
7978
7851
8091
8045
8059
8147
7976
8118
8013
7958
8166
8044
8179
8022
8161
8056
8205
8216
8178
8150
8130
8245
8392
7995
8049
8243
8305
8268
8247
8222
8332
8349
8441
8347
8334
8333
8263
8381
8166
8517
8230
8406
8358
8449
8416
8347
8317
8483
8365
8577
8354
8399
8553
8440
8521
8489
8537
8448
8483
8532
8406
8660
8457
8566
8521
8507
8752
8656
8632
8549
8659
8529
8590
8605
8617
8717
8586
8663
8610
8464
8673
8645
8739
8554
8665
8940
9132
9292
9258
9287
9593
9872
9309
8943
8626
8737
8667
8583
8709
8721
8794
8817
8894
8780
8866
8820
8851
8830
8905
8979
8904
8835
8932
8836
8957
8910
9082
9119
9002
8882
8997
8942
9097
9175
9067
9128
9265
9112
9097
9138
9007
9288
9288
9103
9244
9405
9271
9450
9477
9439
9441
9549
9633
9842
9591
9665
9587
9586
9484
9811
9488
9403
9556
9575
9321
9409
9455
9248
9289
9133
9154
9101
9022
9349
9512
9616
9466
9722
9834
10223
10066
10437
10431
10411
10703
10711
10867
10936
10916
10739
10472
10179
9684
9381
8782
8326
7822
7345
6787
6438
5892
5582
5334
5293
5253
5429
5830
6378
7138
8148
9768
11045
11977
14246
17956
28401
55024
38020
7304
1799
1196
910
796
680
589
558
517
544
539
518
496
493
499
513
476
484
465
514
521
465
483
484
483
484
487
498
463
494
450
509
492
493
493
448
515
478
496
480
516
455
459
506
512
457
463
453
502
516
569
566
514
480
493
519
454
427
500
480
469
484
482
448
474
458
461
464
449
472
467
500
473
462
442
481
441
455
452
474
481
469
503
453
504
455
421
443
515
471
492
513
486
469
475
493
444
464
473
459
437
470
466
464
457
425
502
503
477
457
466
494
521
579
618
601
474
500
442
466
488
448
453
427
437
459
454
466
462
481
463
475
414
475
465
443
441
459
450
435
456
410
469
436
457
477
455
455
473
465
424
488
465
464
447
444
470
480
458
432
444
471
506
447
470
483
452
494
487
469
506
472
491
455
485
450
500
507
493
499
516
511
488
430
469
457
458
491
479
485
498
494
473
525
489
501
475
461
475
492
512
469
457
512
498
494
525
514
518
513
492
501
488
505
525
512
509
509
475
532
516
502
481
509
547
518
557
534
585
572
562
546
556
530
569
549
553
548
597
566
563
532
533
514
472
483
482
491
473
485
460
495
523
566
587
645
696
689
684
665
565
652
757
792
804
799
793
716
664
639
594
503
453
420
369
301
256
226
152
129
29.504
C 1s/8
Not Specified
2017
12
11
13
25
16
0
9
Casa Info Follows
1
Calib M = 280.699 A = 284.5 BE ADD
0
0
0
   XPS     Spectrum    Lens Mode:Hybrid   Resolution:Pass energy 20    Iris(Aper):slot(Slot)
   Acqn. Time(s): 261        Sweeps: 4        Anode:Mono(Al (Mono))(150 W)   Step(meV): 100.0
   Dwell Time(ms): 250        Charge Neutraliser :On   Acquired On :17/12/11 13:25:16
XPS
0
0
0
Mono(Al (Mono))
1486.69
150
1e+037
1e+037
6000
6000
1e+037
1e+037
FAT
20
1e+037
-4.803
0
1e+037
1e+037
1e+037
1e+037
C
1s
-1
Kinetic Energy
eV
1186.69
0.1
2
Intensity
d
Transmission
d
pulse counting
0.25
4
0
1e+037
1e+037
1e+037
0
522
137
30519
1.1574
1.16426
1667
1.16426
1673
1.16422
1641
1.16418
1628
1.16414
1597
1.1641
1622
1.16406
1630
1.16402
1517
1.16398
1572
1.16393
1626
1.16389
1662
1.16385
1544
1.16381
1558
1.16377
1575
1.16373
1483
1.16369
1507
1.16365
1514
1.16361
1468
1.16357
1498
1.16352
1481
1.16348
1421
1.16344
1413
1.1634
1403
1.16336
1470
1.16332
1435
1.16328
1382
1.16324
1334
1.1632
1416
1.16315
1377
1.16311
1315
1.16307
1339
1.16303
1313
1.16299
1260
1.16295
1332
1.16292
1307
1.1629
1320
1.16287
1258
1.16285
1282
1.16282
1247
1.1628
1291
1.16278
1273
1.16275
1300
1.16273
1240
1.1627
1211
1.16268
1190
1.16265
1206
1.16263
1206
1.16261
1250
1.16258
1193
1.16256
1182
1.16253
1264
1.16251
1224
1.16248
1267
1.16246
1162
1.16244
1182
1.16241
1212
1.16239
1192
1.16236
1174
1.16234
1204
1.16231
1126
1.16229
1124
1.16226
1147
1.16224
1151
1.16222
1167
1.16219
1160
1.16217
1150
1.16214
1199
1.16212
1132
1.16209
1172
1.16207
1150
1.16205
1157
1.16202
1138
1.162
1151
1.16197
1171
1.16195
1176
1.16192
1182
1.1619
1129
1.16188
1103
1.16185
1141
1.16183
1216
1.1618
1159
1.16178
1146
1.16175
1175
1.16173
1230
1.16171
1164
1.16168
1251
1.16166
1202
1.16163
1246
1.16161
1283
1.16158
1250
1.16156
1294
1.16153
1288
1.16151
1316
1.16149
1365
1.16146
1376
1.16144
1304
1.16141
1340
1.16139
1339
1.16136
1312
1.16134
1326
1.16132
1386
1.16129
1346
1.16127
1367
1.16124
1372
1.16122
1434
1.16119
1445
1.16117
1431
1.16115
1494
1.16112
1517
1.1611
1425
1.16107
1461
1.16105
1501
1.16102
1572
1.161
1568
1.16097
1607
1.16095
1581
1.16093
1669
1.1609
1714
1.16088
1755
1.16085
1773
1.16083
1770
1.1608
1805
1.16078
1794
1.16076
1810
1.16073
1879
1.16071
1905
1.16068
1935
1.16066
2014
1.16063
1992
1.16061
2011
1.16059
2026
1.16056
2102
1.16054
2085
1.16051
2142
1.16049
2152
1.16046
2203
1.16044
2262
1.16042
2310
1.16039
2307
1.16037
2292
1.16034
2335
1.16032
2307
1.16029
2387
1.16027
2379
1.16024
2425
1.16022
2453
1.1602
2457
1.16017
2482
1.16015
2528
1.16012
2509
1.1601
2540
1.16007
2585
1.16005
2611
1.16003
2557
1.16
2652
1.15998
2628
1.15995
2660
1.15993
2805
1.1599
2839
1.15988
2851
1.15986
2928
1.15983
2952
1.15981
3179
1.15978
3287
1.15976
3375
1.15973
3482
1.15971
3580
1.15969
3761
1.15966
3855
1.15964
4001
1.15961
4091
1.15959
4105
1.15956
4142
1.15954
4099
1.15951
4196
1.15949
4262
1.15947
4356
1.15944
4476
1.15942
4568
1.15939
4609
1.15937
4936
1.15934
5110
1.15932
5547
1.1593
6108
1.15927
6817
1.15925
7751
1.15922
8975
1.1592
10836
1.15917
13410
1.15915
16826
1.15913
21361
1.1591
26274
1.15908
30128
1.15905
30519
1.15903
26788
1.159
20714
1.15898
14224
1.15895
9337
1.15893
5835
1.15891
3733
1.15888
2488
1.15886
1764
1.15883
1231
1.15881
942
1.15878
723
1.15876
594
1.15874
501
1.15871
446
1.15869
377
1.15866
367
1.15864
330
1.15861
299
1.15859
305
1.15857
274
1.15854
294
1.15852
249
1.15849
243
1.15847
237
1.15844
226
1.15842
218
1.1584
237
1.15837
207
1.15835
201
1.15832
192
1.1583
179
1.15827
190
1.15825
180
1.15822
164
1.1582
183
1.15818
183
1.15815
164
1.15813
151
1.1581
175
1.15808
182
1.15805
150
1.15803
179
1.15801
158
1.15798
172
1.15796
163
1.15793
153
1.15791
164
1.15788
137
1.15786
140
1.15784
144
1.15781
150
1.15779
148
1.15776
151
1.15774
146
1.15771
137
1.15769
152
1.15767
156
1.15764
167
1.15762
139
1.15759
155
1.15757
159
1.15754
168
1.15752
141
1.15749
138
1.15747
153
1.15745
147
1.15742
155
1.1574
N 1s/9
Not Specified
2017
12
11
13
25
16
0
9
Casa Info Follows
1
Calib M = 280.699 A = 284.5 BE ADD
0
0
0
   XPS     Spectrum    Lens Mode:Hybrid   Resolution:Pass energy 20    Iris(Aper):slot(Slot)
   Acqn. Time(s): 241        Sweeps: 4        Anode:Mono(Al (Mono))(150 W)   Step(meV): 100.0
   Dwell Time(ms): 298        Charge Neutraliser :On   Acquired On :17/12/11 13:25:16
XPS
0
0
0
Mono(Al (Mono))
1486.69
150
1e+037
1e+037
6000
6000
1e+037
1e+037
FAT
20
1e+037
-4.803
0
1e+037
1e+037
1e+037
1e+037
N
1s
-1
Kinetic Energy
eV
1076.69
0.1
2
Intensity
d
Transmission
d
pulse counting
0.2985
4
0
1e+037
1e+037
1e+037
0
404
2339
2961
1.20216
1.21679
2403
1.21679
2430
1.21671
2435
1.21664
2464
1.21657
2456
1.2165
2469
1.21642
2501
1.21635
2482
1.21628
2489
1.21621
2452
1.21613
2431
1.21606
2393
1.21599
2438
1.21591
2375
1.21584
2420
1.21577
2439
1.2157
2520
1.21562
2498
1.21555
2419
1.21548
2451
1.2154
2456
1.21533
2394
1.21526
2382
1.21519
2380
1.21511
2462
1.21504
2463
1.21497
2413
1.2149
2463
1.21482
2365
1.21475
2401
1.21468
2404
1.2146
2447
1.21453
2486
1.21446
2441
1.21439
2515
1.21431
2472
1.21424
2478
1.21417
2445
1.2141
2513
1.21402
2408
1.21395
2465
1.21388
2441
1.2138
2406
1.21373
2441
1.21366
2424
1.21359
2407
1.21351
2433
1.21344
2376
1.21337
2358
1.21329
2376
1.21322
2402
1.21315
2428
1.21308
2451
1.213
2482
1.21293
2405
1.21286
2417
1.21279
2453
1.21271
2449
1.21264
2443
1.21257
2480
1.21249
2448
1.21242
2478
1.21235
2395
1.21228
2415
1.2122
2397
1.21213
2499
1.21206
2453
1.21198
2467
1.21191
2505
1.21184
2497
1.21177
2501
1.21169
2408
1.21162
2505
1.21155
2442
1.21148
2458
1.2114
2411
1.21133
2474
1.21126
2486
1.21118
2483
1.21111
2482
1.21104
2479
1.21097
2455
1.21089
2477
1.21082
2478
1.21075
2566
1.21068
2562
1.2106
2586
1.21053
2530
1.21046
2584
1.21038
2622
1.21031
2629
1.21024
2757
1.21017
2710
1.21009
2724
1.21002
2811
1.20995
2792
1.20987
2668
1.2098
2680
1.20973
2635
1.20966
2596
1.20958
2657
1.20951
2617
1.20944
2675
1.20937
2651
1.20929
2614
1.20922
2613
1.20915
2611
1.20907
2573
1.209
2531
1.20893
2525
1.20886
2583
1.20878
2605
1.20871
2603
1.20864
2554
1.20856
2510
1.20849
2561
1.20842
2586
1.20835
2610
1.20827
2569
1.2082
2556
1.20813
2578
1.20806
2633
1.20798
2584
1.20791
2642
1.20784
2652
1.20776
2609
1.20769
2646
1.20762
2717
1.20755
2653
1.20747
2733
1.2074
2745
1.20733
2774
1.20726
2780
1.20718
2800
1.20711
2792
1.20704
2884
1.20696
2914
1.20689
2892
1.20682
2937
1.20675
2961
1.20667
2922
1.2066
2938
1.20653
2856
1.20645
2859
1.20638
2846
1.20631
2826
1.20624
2751
1.20616
2726
1.20609
2661
1.20602
2506
1.20595
2608
1.20587
2593
1.2058
2490
1.20573
2509
1.20565
2483
1.20558
2501
1.20551
2493
1.20544
2488
1.20536
2478
1.20529
2366
1.20522
2387
1.20514
2474
1.20507
2424
1.205
2422
1.20493
2339
1.20485
2452
1.20478
2457
1.20471
2453
1.20464
2433
1.20456
2447
1.20449
2411
1.20442
2419
1.20434
2441
1.20427
2452
1.2042
2435
1.20413
2457
1.20405
2456
1.20398
2437
1.20391
2488
1.20384
2471
1.20376
2488
1.20369
2483
1.20362
2457
1.20354
2465
1.20347
2381
1.2034
2449
1.20333
2357
1.20325
2393
1.20318
2421
1.20311
2455
1.20303
2435
1.20296
2393
1.20289
2396
1.20282
2453
1.20274
2408
1.20267
2447
1.2026
2439
1.20253
2490
1.20245
2481
1.20238
2451
1.20231
2430
1.20223
2462
1.20216
Survey/12
Not Specified
2017
12
11
13
35
42
0
16
Casa Info Follows
1
Calib M = 284.103 A = 284.5 BE ADD
1
annot regions Display 0.05 0.05 RGB(0,0,0) Font(12,18,0,0,Times New Roman)

5
CASA region (*C 1s*) (*Shirley*) 1188.6016 1207.043 0.278 1 0 0 299 542 275 9.3 (*C 1s*) 12.011
CASA region (*F 1s*) (*Shirley*) 798.043 803.88178 1 1 0 0 299 542 275 9.3 (*F 1s*) 18.9984
CASA region (*O 1s*) (*Shirley*) 945.543 958.71196 0.78 1 0 0 299 542 275 9.3 (*O 1s*) 15.9994
CASA region (*S 2p*) (*Shirley*) 1314.043 1322.543 0.668 1 0 0 299 542 275 9.3 (*S 2p*) 32.0648
CASA region (*N 1s*) (*Shirley*) 1082.4711 1088.8203 0.477 1 0 0 299 542 275 9.3 (*N 1s*) 14.0067
0
   XPS     Spectrum    Lens Mode:Hybrid   Resolution:Pass energy 160   Iris(Aper):slot(Slot)
   Acqn. Time(s): 540        Sweeps: 2        Anode:Mono(Al (Mono))(150 W)   Step(meV): 500.0
   Dwell Time(ms): 100        Charge Neutraliser :On   Acquired On :17/12/11 13:35:42
XPS
10
1
0
Mono(Al (Mono))
1486.69
150
1e+037
1e+037
6000
6000
1e+037
1e+037
FAT
160
1e+037
-4.803
0
1e+037
1e+037
1e+037
1e+037
Wide
None
-1
Kinetic Energy
eV
136.69
0.5
2
Intensity
d
Transmission
d
pulse counting
0.1
1e+037
22
9700
9687
9592
9886
9676
9701
9667
9678
9566
9676
9703
9780
9851
9657
9795
9799
9588
9682
9684
9499
9600
9716
9649
9781
9605
9763
9656
9627
9699
9609
9614
9533
9499
9701
9564
9580
9621
9585
9565
9519
9540
9609
9769
9879
10030
10289
10487
10323
10006
9883
9843
9892
9719
9906
9862
10026
9895
10169
9909
9974
10141
9895
9961
10181
10087
10023
10194
10193
10216
10313
10285
10182
10351
10188
10372
10283
10307
10408
10460
10519
10406
10507
10559
10674
10553
10624
10638
10694
10591
10980
10817
10808
10851
10809
11101
10960
10927
11084
11081
11141
11169
11422
11310
11609
11671
11624
11580
11616
11598
11708
11608
11486
11458
11395
11501
11773
11705
12173
12300
12463
12540
12649
12579
12746
12888
12864
12881
12590
12761
12494
12473
12434
12229
11830
11514
11015
10559
10130
9732
9381
8829
8530
8147
7818
7637
7413
7166
6993
7057
6899
6958
6810
6936
6982
6911
6877
6952
6978
6977
7070
6921
6947
7007
6884
7007
6828
6920
6935
7179
6982
6974
7062
7035
7129
7081
7021
7114
7111
6935
6998
7023
7083
7167
7225
7195
7110
7214
7193
7294
7166
7265
7219
7286
7207
7325
7269
7273
7203
7412
7302
7164
7288
7349
7395
7319
7363
7354
7445
7361
7370
7445
7433
7422
7496
7464
7574
7433
7676
7518
7539
7562
7450
7533
7599
7574
7578
7527
7468
7682
7607
7662
7708
7673
7671
7617
7520
7679
7870
7867
7797
7792
7665
7682
7652
7836
7624
7692
7907
7926
7772
7776
7882
7914
7717
7884
7960
7864
7899
7883
7895
7771
7990
7902
7892
7902
7966
7950
7993
7948
8072
8016
7982
8040
8097
8175
8021
8035
8071
8329
8190
8072
8218
8055
8123
8238
8142
8170
8207
8292
8308
8186
8385
8265
8284
8258
8412
8394
8300
8381
8328
8440
8496
8394
8571
8640
8737
8529
8448
8534
8521
8597
8553
8600
8709
8602
8615
8627
8612
8693
8723
8721
8715
8879
8820
8734
8841
8898
8910
9052
9115
9013
8834
9223
9078
9032
8985
9078
9107
9192
9037
9029
9145
9197
9279
9258
9315
9365
9719
9679
9690
9761
9743
9612
9572
9482
9505
9533
9239
9211
9065
8811
8771
8868
8883
9027
9055
9245
9293
9475
9668
10122
10265
10503
10624
10566
10580
10353
10168
10072
9495
9280
8927
8593
8050
7828
7550
7298
7193
7234
7049
7073
7048
6991
6993
7014
6976
6905
7136
7105
7046
7011
6932
7135
7054
6975
7064
7086
7000
7168
7031
7168
7142
6981
7144
7082
7149
7175
7241
7206
7203
7102
7094
7165
7178
7230
7198
7251
7207
7180
7213
7329
7057
7204
7321
7273
7353
7388
7251
7289
7512
7308
7169
7330
7333
7271
7444
7372
7366
7516
7430
7421
7377
7422
7352
7328
7477
7468
7621
7533
7504
7401
7573
7381
7580
7579
7441
7559
7606
7604
7509
7536
7671
7580
7649
7616
7535
7623
7454
7713
7602
7633
7597
7638
7607
7632
7621
7748
7688
7657
7710
7681
7689
7709
7791
7699
7818
7746
7809
7912
7846
7725
7784
7784
7818
7868
7885
7858
7709
7943
7802
7742
7779
7838
7896
7879
7811
7864
8002
7919
8168
8027
8079
8018
8012
8146
8066
7990
8002
7789
7993
7917
7834
7964
7887
7970
8017
7874
7868
7969
7923
8042
7904
8145
7900
8104
8020
8015
8118
8010
8191
8258
8007
8098
8059
8130
8069
8295
8226
8050
8126
8181
8180
8022
8196
8357
8259
8256
8256
8328
8300
8309
8090
8220
8275
8284
8417
8385
8376
8324
8323
8376
8388
8387
8252
8461
8504
8277
8418
8461
8494
8478
8448
8361
8533
8315
8417
8562
8423
8474
8581
8685
8576
8474
8482
8559
8574
8536
8677
8707
8650
8592
8585
8765
8655
8703
8825
8796
8583
8582
8799
8806
8572
8867
8761
8859
8783
8733
8720
8704
8658
8858
8872
8777
8794
8790
8835
8853
8853
8898
9063
9019
8954
8936
8952
8918
9043
8933
8881
8851
9014
9051
8967
8950
8985
8926
8984
8923
8916
8943
8955
9141
8995
9118
9162
9605
9744
9589
9186
9025
8932
9212
9178
9175
9010
9281
9184
9075
9101
9203
9240
9144
9182
9133
9345
9190
9215
9233
9260
9278
9168
9456
9415
9274
9184
9242
9400
9434
9282
9335
9185
9302
9433
9454
9598
9490
9280
9532
9488
9502
9459
9269
9399
9476
9623
9704
9541
9319
9471
9742
9588
9593
9618
9701
9655
9576
9557
9719
9749
9639
9596
9796
9763
9756
9706
9798
9712
9909
9855
9765
9800
9886
9671
9885
9825
9892
9931
9744
9979
9617
9809
9917
9998
9855
9966
9982
9950
10128
9915
9939
10176
10091
10001
10051
10167
10218
10131
10265
10090
10151
10307
10036
9955
10128
10263
10249
10104
10141
10101
10148
10179
10198
10094
10071
10107
10198
10385
10354
10380
10610
10638
10676
10751
10766
10688
10719
10524
10554
10490
10175
10126
9874
9596
9609
9507
9232
9262
8963
8931
8915
8920
8943
8937
9162
9346
9730
11197
15326
22370
25821
20265
12688
8779
7792
7741
7744
7623
7616
7588
7610
7583
7539
7765
7491
7566
7540
7661
7617
7585
7585
7517
7675
7705
7761
7653
7527
7663
7666
7809
7611
7784
7668
7657
7748
7922
7761
7652
7733
7834
7886
7607
7792
7819
7735
7892
7781
7883
7699
7802
8010
7865
7905
7898
7895
7937
7699
7986
7972
7906
8054
7900
7909
7993
8056
8015
8003
7995
8089
8135
8122
7979
8048
8114
8138
8111
8134
8173
8128
8243
8119
8036
8209
8216
8099
8147
8170
8145
8181
8293
8384
8434
8340
8376
8446
8347
8280
8346
8331
8345
8465
8408
8578
8517
8467
8388
8246
8445
8457
8485
8523
8522
8401
8368
8581
8391
8424
8614
8552
8518
8567
8498
8496
8665
8595
8592
8586
8667
8718
8738
9157
9279
9208
9060
8718
8737
8687
8700
8593
8646
8674
8847
8794
8846
8683
8695
8810
8955
8836
8930
8800
8888
8897
8830
8939
9088
9034
8991
8909
8983
9004
9083
9109
9166
8996
9032
8992
9167
9215
9237
9354
9278
9134
9282
9195
9306
9333
9427
9533
9561
9628
9673
9768
9534
9900
9927
9678
9607
9660
9697
9546
9594
9642
9587
9686
9359
9500
9433
9189
9374
9275
9325
9301
9399
9337
9440
9356
9613
9936
9932
10068
10125
10250
10478
10592
10550
10584
10690
10763
10796
10838
10679
10598
10325
10168
9973
9258
8425
7841
7412
6810
6383
6020
5690
5551
5465
5575
5562
6082
6554
7305
8216
9134
10409
12494
16644
23606
40115
53329
24448
3654
1667
1275
1027
864
767
739
712
623
668
696
678
692
671
646
636
645
678
639
634
670
645
656
676
674
692
669
671
667
669
696
684
623
687
644
654
638
629
660
650
627
618
630
607
673
654
642
683
739
840
914
852
760
685
625
639
640
626
640
626
632
635
574
656
633
636
619
599
624
617
599
630
598
628
631
589
594
582
655
601
665
660
679
594
627
647
665
641
628
684
682
661
630
645
624
605
618
656
626
610
575
607
599
554
570
606
607
605
581
602
605
641
778
967
1099
927
662
605
557
557
550
541
590
629
575
619
671
687
693
666
602
604
535
569
604
559
555
559
560
594
589
567
553
596
572
593
594
585
559
572
569
587
609
565
596
548
612
607
562
572
560
599
578
587
591
581
565
601
581
582
596
579
602
595
607
604
610
656
710
724
688
658
621
597
588
565
575
584
570
593
606
619
647
683
631
620
560
567
598
611
614
596
625
602
594
617
628
599
607
641
610
600
593
606
604
584
607
638
616
597
601
614
615
624
602
668
648
701
660
688
760
698
742
707
652
664
683
683
657
646
637
636
612
610
563
611
555
581
524
552
607
596
665
778
839
913
894
943
834
768
662
723
790
817
854
827
822
812
761
702
635
552
560
549
482
368
305
256
195
133
84
35
22
29.504
C 1s/13
Not Specified
2017
12
11
13
47
44
0
9
Casa Info Follows
1
Calib M = 284.103 A = 284.5 BE ADD
0
0
0
   XPS     Spectrum    Lens Mode:Hybrid   Resolution:Pass energy 20    Iris(Aper):slot(Slot)
   Acqn. Time(s): 261        Sweeps: 4        Anode:Mono(Al (Mono))(150 W)   Step(meV): 100.0
   Dwell Time(ms): 250        Charge Neutraliser :On   Acquired On :17/12/11 13:47:44
XPS
10
1
0
Mono(Al (Mono))
1486.69
150
1e+037
1e+037
6000
6000
1e+037
1e+037
FAT
20
1e+037
-4.803
0
1e+037
1e+037
1e+037
1e+037
C
1s
-1
Kinetic Energy
eV
1186.69
0.1
2
Intensity
d
Transmission
d
pulse counting
0.25
4
0
1e+037
1e+037
1e+037
0
522
141
24713
1.1574
1.16426
1201
1.16426
1217
1.16422
1199
1.16418
1248
1.16414
1231
1.1641
1185
1.16406
1232
1.16402
1201
1.16398
1123
1.16393
1177
1.16389
1169
1.16385
1109
1.16381
1116
1.16377
1095
1.16373
1153
1.16369
1118
1.16365
1141
1.16361
1164
1.16357
1077
1.16352
1126
1.16348
1145
1.16344
1150
1.1634
1119
1.16336
1081
1.16332
1073
1.16328
1043
1.16324
1105
1.1632
1126
1.16315
1094
1.16311
1106
1.16307
1072
1.16303
1077
1.16299
1069
1.16295
1076
1.16292
1051
1.1629
1107
1.16287
1039
1.16285
1112
1.16282
1089
1.1628
1090
1.16278
1127
1.16275
1092
1.16273
1106
1.1627
1064
1.16268
1085
1.16265
1096
1.16263
1115
1.16261
1146
1.16258
1163
1.16256
1168
1.16253
1129
1.16251
1158
1.16248
1124
1.16246
1202
1.16244
1215
1.16241
1156
1.16239
1170
1.16236
1273
1.16234
1228
1.16231
1233
1.16229
1297
1.16226
1308
1.16224
1198
1.16222
1205
1.16219
1274
1.16217
1265
1.16214
1263
1.16212
1218
1.16209
1271
1.16207
1268
1.16205
1301
1.16202
1244
1.162
1265
1.16197
1288
1.16195
1365
1.16192
1323
1.1619
1302
1.16188
1308
1.16185
1389
1.16183
1415
1.1618
1398
1.16178
1401
1.16175
1459
1.16173
1516
1.16171
1495
1.16168
1512
1.16166
1571
1.16163
1547
1.16161
1559
1.16158
1614
1.16156
1602
1.16153
1685
1.16151
1622
1.16149
1686
1.16146
1655
1.16144
1637
1.16141
1662
1.16139
1681
1.16136
1674
1.16134
1732
1.16132
1638
1.16129
1683
1.16127
1689
1.16124
1732
1.16122
1739
1.16119
[...]
1.16107
1935
1.16105
2069
1.16102
2048
1.161
2070
1.16097
2109
1.16095
2103
1.16093
2076
1.1609
2086
1.16088
2111
1.16085
2121
1.16083
2131
1.1608
2260
1.16078
2193
1.16076
2234
1.16073
2307
1.16071
2434
1.16068
2540
1.16066
2691
1.16063
2841
1.16061
3057
1.16059
3238
1.16056
3476
1.16054
3677
1.16051
3964
1.16049
4057
1.16046
4141
1.16044
4368
1.16042
4418
1.16039
4390
1.16037
4457
1.16034
4386
1.16032
4426
1.16029
4314
1.16027
4340
1.16024
4643
1.16022
4751
1.1602
4955
1.16017
5367
1.16015
5762
1.16012
6302
1.1601
6913
1.16007
7727
1.16005
8966
1.16003
10575
1.16
12735
1.15998
15349
1.15995
18589
1.15993
22455
1.1599
24644
1.15988
24713
1.15986
22117
1.15983
18079
1.15981
13525
1.15978
9450
1.15976
6308
1.15973
4121
1.15971
2648
1.15969
1751
1.15966
1307
1.15964
977
1.15961
746
1.15959
586
1.15956
514
1.15954
457
1.15951
420
1.15949
392
1.15947
363
1.15944
312
1.15942
329
1.15939
296
1.15937
268
1.15934
255
1.15932
273
1.1593
240
1.15927
218
1.15925
250
1.15922
238
1.1592
219
1.15917
231
1.15915
236
1.15913
220
1.1591
196
1.15908
206
1.15905
184
1.15903
224
1.159
208
1.15898
196
1.15895
194
1.15893
181
1.15891
195
1.15888
189
1.15886
198
1.15883
186
1.15881
199
1.15878
196
1.15876
185
1.15874
170
1.15871
191
1.15869
165
1.15866
206
1.15864
181
1.15861
175
1.15859
176
1.15857
180
1.15854
178
1.15852
190
1.15849
196
1.15847
183
1.15844
171
1.15842
161
1.1584
185
1.15837
208
1.15835
175
1.15832
166
1.1583
148
1.15827
158
1.15825
167
1.15822
150
1.1582
153
1.15818
166
1.15815
165
1.15813
172
1.1581
161
1.15808
186
1.15805
185
1.15803
186
1.15801
181
1.15798
165
1.15796
168
1.15793
161
1.15791
179
1.15788
168
1.15786
160
1.15784
174
1.15781
152
1.15779
167
1.15776
141
1.15774
166
1.15771
167
1.15769
179
1.15767
147
1.15764
152
1.15762
158
1.15759
173
1.15757
170
1.15754
147
1.15752
158
1.15749
186
1.15747
162
1.15745
152
1.15742
154
1.1574
N 1s/14
Not Specified
2017
12
11
13
47
44
0
9
Casa Info Follows
1
Calib M = 284.103 A = 284.5 BE ADD
0
0
0
   XPS     Spectrum    Lens Mode:Hybrid   Resolution:Pass energy 20    Iris(Aper):slot(Slot)
   Acqn. Time(s): 241        Sweeps: 4        Anode:Mono(Al (Mono))(150 W)   Step(meV): 100.0
   Dwell Time(ms): 298        Charge Neutraliser :On   Acquired On :17/12/11 13:47:44
XPS
10
1
0
Mono(Al (Mono))
1486.69
150
1e+037
1e+037
6000
6000
1e+037
1e+037
FAT
20
1e+037
-4.803
0
1e+037
1e+037
1e+037
1e+037
N
1s
-1
Kinetic Energy
eV
1076.69
0.1
2
Intensity
d
Transmission
d
pulse counting
0.2985
4
0
1e+037
1e+037
1e+037
0
404
2134
2453
1.20216
1.21679
2174
1.21679
2179
1.21671
2215
1.21664
2205
1.21657
2181
1.2165
2200
1.21642
2205
1.21635
2154
1.21628
2247
1.21621
2276
1.21613
2157
1.21606
2173
1.21599
2174
1.21591
2236
1.21584
2218
1.21577
2220
1.2157
2223
1.21562
2255
1.21555
2238
1.21548
2246
1.2154
2169
1.21533
2282
1.21526
2241
1.21519
2200
1.21511
2175
1.21504
2166
1.21497
2199
1.2149
2181
1.21482
2187
1.21475
2247
1.21468
2215
1.2146
2256
1.21453
2184
1.21446
2237
1.21439
2291
1.21431
2209
1.21424
2251
1.21417
2234
1.2141
2204
1.21402
2225
1.21395
2237
1.21388
2291
1.2138
2257
1.21373
2262
1.21366
2251
1.21359
2313
1.21351
2290
1.21344
2298
1.21337
2227
1.21329
2223
1.21322
2134
1.21315
2273
1.21308
2261
1.213
2232
1.21293
2244
1.21286
2273
1.21279
2237
1.21271
2198
1.21264
2220
1.21257
2243
1.21249
2248
1.21242
2186
1.21235
2206
1.21228
2192
1.2122
2199
1.21213
2237
1.21206
2263
1.21198
2291
1.21191
2252
1.21184
2321
1.21177
2222
1.21169
2282
1.21162
2298
1.21155
2361
1.21148
2357
1.2114
2316
1.21133
2311
1.21126
2261
1.21118
2354
1.21111
2318
1.21104
2406
1.21097
2386
1.21089
2360
1.21082
2342
1.21075
2396
1.21068
2440
1.2106
2429
1.21053
2417
1.21046
2449
1.21038
2405
1.21031
2453
1.21024
2422
1.21017
2379
1.21009
2427
1.21002
2371
1.20995
2334
1.20987
2359
1.2098
2290
1.20973
2414
1.20966
2400
1.20958
2399
1.20951
2361
1.20944
2320
1.20937
2297
1.20929
2414
1.20922
2362
1.20915
2384
1.20907
2373
1.209
2345
1.20893
2372
1.20886
2355
1.20878
2341
1.20871
2318
1.20864
2305
1.20856
2317
1.20849
2390
1.20842
2254
1.20835
2269
1.20827
2209
1.2082
2299
1.20813
2206
1.20806
2151
1.20798
2229
1.20791
2248
1.20784
2182
1.20776
2224
1.20769
2180
1.20762
2224
1.20755
2225
1.20747
2278
1.2074
2298
1.20733
2247
1.20726
2243
1.20718
2226
1.20711
2172
1.20704
2225
1.20696
2224
1.20689
2274
1.20682
2251
1.20675
2279
1.20667
2267
1.2066
2268
1.20653
2202
1.20645
2206
1.20638
2194
1.20631
2221
1.20624
2213
1.20616
2229
1.20609
2254
1.20602
2208
1.20595
2291
1.20587
2340
1.2058
2264
1.20573
2182
1.20565
2225
1.20558
2251
1.20551
2195
1.20544
2247
1.20536
2243
1.20529
2207
1.20522
2177
1.20514
2218
1.20507
2224
1.205
2235
1.20493
2282
1.20485
2286
1.20478
2271
1.20471
2246
1.20464
2217
1.20456
2286
1.20449
2236
1.20442
2264
1.20434
2262
1.20427
2253
1.2042
2207
1.20413
2229
1.20405
2333
1.20398
2244
1.20391
2245
1.20384
2238
1.20376
2260
1.20369
2254
1.20362
2211
1.20354
2244
1.20347
2234
1.2034
2257
1.20333
2215
1.20325
2256
1.20318
2215
1.20311
2295
1.20303
2248
1.20296
2191
1.20289
2205
1.20282
2151
1.20274
2228
1.20267
2186
1.2026
2287
1.20253
2276
1.20245
2291
1.20238
2228
1.20231
2234
1.20223
2201
1.20216
Survey/17
Not Specified
2017
12
11
13
58
7
0
16
Casa Info Follows
1
Calib M = 284.186 A = 284.5 BE ADD
1
annot regions Display 0.05 0.05 RGB(0,0,0) Font(12,18,0,0,Times New Roman)

5
CASA region (*O 1s*) (*Shirley*) 947.28312 959.18278 0.78 1 0 0 299 542 275 9.3 (*O 1s*) 15.9994
CASA region (*C 1s*) (*Shirley*) 1189.2363 1207.626 0.278 1 0 0 299 542 275 9.3 (*C 1s*) 12.011
CASA region (*N 1s*) (*Shirley*) 1082.126 1089.9494 0.477 1 0 0 299 542 275 9.3 (*N 1s*) 14.0067
CASA region (*S 2p*) (*Shirley*) 1314.3284 1321.4486 0.668 1 0 0 299 542 275 9.3 (*S 2p*) 32.0648
CASA region (*F 1s*) (*Shirley*) 798.57398 803.06077 1 1 0 0 299 542 275 9.3 (*F 1s*) 18.9984
0
   XPS     Spectrum    Lens Mode:Hybrid   Resolution:Pass energy 160   Iris(Aper):slot(Slot)
   Acqn. Time(s): 540        Sweeps: 2        Anode:Mono(Al (Mono))(150 W)   Step(meV): 500.0
   Dwell Time(ms): 100        Charge Neutraliser :On   Acquired On :17/12/11 13:58:07
XPS
14
1
0
Mono(Al (Mono))
1486.69
150
1e+037
1e+037
6000
6000
1e+037
1e+037
FAT
160
1e+037
-4.803
0
1e+037
1e+037
1e+037
1e+037
Wide
None
-1
Kinetic Energy
eV
136.69
0.5
2
Intensity
d
Transmission
d
pulse counting
0.1
1e+037
14
7961
7965
8081
8045
8085
7900
8098
8031
8009
8003
7757
7916
8179
7907
7872
7972
7845
8038
8015
8064
8113
7973
8020
8062
8114
7995
8082
7878
8082
8000
7999
8104
8139
7927
8253
8041
8134
8046
7981
8078
8035
8196
8089
8149
8403
8823
9143
8859
8507
8268
8392
8341
8382
8251
8171
8307
8287
8138
8482
8555
8458
8500
8510
8317
8372
8620
8550
8477
8550
8716
8661
8655
8698
8675
8672
8626
8759
8918
8827
8858
8948
8863
8791
8934
8888
8951
9006
9206
9085
8991
8942
9216
9071
9277
9226
9196
9371
9444
9382
9322
9423
9409
9662
9805
9826
9705
9765
9607
9717
9820
9841
9830
9851
9671
9696
9909
10068
10294
10267
10399
10623
10616
10742
10924
10829
10755
10914
10858
10781
10700
10713
10421
10300
10181
10023
9540
9102
8824
8418
8162
7538
7365
6997
6658
6459
6161
5997
5875
5954
5905
5765
5810
5893
5806
5968
5842
5752
5794
5888
5802
5860
5903
5897
5959
5911
5933
5870
5917
5917
6049
5880
5919
5932
6008
5880
6104
5969
5984
6028
6054
6080
5935
6060
6070
6136
6120
6056
6118
6088
6160
6051
6087
6015
5981
6032
6222
6157
6141
6164
6326
6212
6136
6181
6187
6199
6189
6266
6113
6251
6236
6343
6351
6201
6365
6251
6237
6344
6232
6231
6358
6391
6431
6291
6466
6271
6441
6457
6384
6376
6495
6553
6393
6380
6471
6526
6467
6498
6420
6442
6457
6574
6641
6547
6545
6521
6547
6575
6600
6595
6589
6596
6700
6618
6674
6739
6584
6508
6569
6599
6551
6502
6498
6713
6565
6784
6670
6743
6722
6765
6786
6819
6739
6657
6766
6831
6805
6804
6795
6808
6848
6846
6874
6937
6899
6887
6914
6810
6821
6871
6901
6877
6901
6861
6924
6971
7050
7091
7105
7053
7065
7102
7045
6982
7052
7209
7084
7173
7223
7139
7154
7211
7171
7076
7231
7273
7257
7333
7229
7406
7195
7418
7403
7276
7324
7353
7410
7471
7542
7458
7426
7462
7485
7600
7508
7610
7449
7558
7550
7438
7493
7476
7674
7575
7578
7753
7849
7922
7874
8032
8174
8148
8138
7948
8062
7947
7905
7701
7797
7536
7607
7531
7417
7539
7395
7553
7552
7718
7700
7962
8310
8331
8493
8765
8760
8805
8777
8493
8505
8075
8021
7817
7384
7192
6880
6487
6358
6257
6196
6094
5982
5938
6053
5961
5986
6005
5955
5905
5944
5950
5938
5962
5958
5887
6042
6077
5991
6053
6031
5991
6038
6070
6057
6082
6014
6068
6051
6180
6045
6101
6171
6011
6088
6198
6109
6085
6078
6210
6094
5952
6226
6107
5996
6135
6254
6142
6152
6067
6127
6218
6109
6229
6174
6245
6236
6198
6341
6285
6260
6248
6165
6321
6298
6222
6257
6215
6304
6385
6397
6266
6260
6233
6290
6351
6344
6468
6426
6303
6403
6338
6360
6437
6477
6509
6328
6391
6496
6391
6369
6443
6491
6414
6479
6365
6475
6518
6361
6482
6442
6435
6523
6499
6502
6536
6576
6544
6642
6436
6525
6513
6579
6422
6458
6550
6586
6663
6580
6553
6665
6622
6570
6593
6650
6639
6651
6600
6787
6688
6730
6691
6664
6630
6599
6674
6748
6828
6671
6712
6703
6868
6730
6665
6677
6798
6614
6806
6760
6659
6700
6694
6702
6784
6719
6806
6730
6709
6755
6740
6846
6891
6903
6843
6830
6841
6913
6829
6855
6922
6861
6896
6773
6954
6845
6880
6933
6992
6902
6904
6986
6985
6981
6998
6938
6938
6928
7051
7069
7030
6989
7104
7075
7073
6980
7042
7075
7122
7099
7000
7077
7095
7015
7105
7207
6996
7032
7149
7105
7181
7168
7091
7302
7262
7051
7233
7192
7192
7210
7255
7199
7203
7261
7173
7333
7310
7320
7208
7309
7169
7317
7310
7299
7235
7292
7332
7285
7273
7306
7305
7443
7383
7420
7355
7463
7481
7442
7406
7485
7430
7517
7458
7475
7479
7442
7465
7367
7560
7424
7469
7358
7501
7498
7459
7429
7505
7354
7580
7470
7572
7464
7562
7533
7602
7652
7596
7774
7880
7928
7721
7607
7659
7584
7668
7575
7468
7470
7480
7613
7626
7638
7706
7635
7728
7641
7665
7684
7645
7808
7850
7817
7784
7618
7812
7918
7660
7715
7759
7795
7801
7838
7683
7834
7717
7816
7798
7755
8039
7868
7865
7776
7922
7902
7992
7947
8036
8019
7931
7928
7895
7994
7978
7912
7994
8007
8005
8078
8105
7925
7999
8046
8026
8122
7926
8070
7968
8013
8050
7984
8108
8040
8109
8097
8252
8071
8118
8191
8139
8058
8180
8136
8297
8210
8185
8262
8398
8210
8347
8167
8316
8275
8175
8209
8309
8341
8288
8266
8541
8329
8328
8364
8196
8341
8410
8436
8433
8365
8398
8326
8355
8357
8312
8491
8416
8234
8478
8283
8428
8576
8520
8557
8700
8720
9002
8929
8894
8866
8983
8788
8584
8545
8473
8292
8164
7945
7891
7854
7638
7561
7468
7473
7316
7340
7408
7320
7648
7891
8124
9370
12041
17745
20986
17232
11191
7479
6718
6453
6464
6554
6476
6472
6438
6384
6355
6424
6399
6418
6329
6451
6428
6494
6472
6563
6433
6328
6443
6451
6503
6431
6527
6577
6477
6534
6556
6498
6521
6588
6742
6647
6538
6550
6573
6489
6645
6562
6594
6672
6656
6674
6593
6635
6676
6585
6650
6641
6567
6690
6666
6604
6679
6700
6697
6741
6705
6737
6617
6744
6851
6851
6728
6797
6769
6778
6809
6760
6854
6797
6871
6799
6832
6806
6901
6835
6901
6892
6904
6978
6970
6984
6977
6870
6959
6992
6950
7109
7017
6974
7024
7050
7087
6997
7205
7015
6987
7168
7040
7010
6986
7038
7043
7068
7151
7065
6956
7147
7087
7110
7097
7069
7149
7109
7155
7119
7159
7182
7206
7273
7200
7312
7222
7313
7609
7843
7690
7580
7531
7208
7177
7315
7344
7213
7303
7233
7292
7356
7451
7362
7318
7335
7444
7462
7546
7467
7323
7612
7400
7505
7604
7587
7440
7576
7665
7512
7443
7561
7688
7646
7685
7531
7581
7685
7515
7705
7727
7575
7682
7709
7742
7849
7896
7863
8089
8126
8028
8111
8033
8101
8138
8011
8067
8070
7983
8112
7986
8114
8038
7918
7868
7840
7858
7822
7769
7785
7720
7703
7789
7719
7894
8004
8110
8178
8456
8528
8680
8747
8634
8850
8822
9054
9063
9031
9180
9074
8814
8814
8555
8427
7843
7064
6519
6092
5749
5352
4924
4778
4685
4535
4623
5016
5186
5612
6150
7026
7706
8670
9977
12876
18189
34062
46286
20066
3192
1549
1097
906
811
755
662
670
623
648
614
598
655
658
621
647
569
590
616
620
639
620
613
625
620
627
646
630
619
599
608
591
599
594
604
567
577
594
604
581
560
603
540
597
573
625
580
608
759
839
958
900
686
626
601
589
587
565
580
549
551
537
498
550
567
548
549
545
573
560
579
520
529
585
553
561
559
535
579
552
565
568
582
596
544
581
578
580
629
558
648
605
585
545
597
585
523
523
526
566
549
499
547
543
507
506
519
517
535
523
543
582
704
1014
1174
904
556
532
509
504
464
461
512
566
531
533
568
625
632
577
558
500
480
481
482
476
461
487
460
479
473
461
462
453
447
474
433
486
462
443
509
471
438
491
461
462
450
474
487
512
477
499
501
474
473
495
495
479
465
447
460
449
457
472
458
498
506
577
670
638
591
538
481
474
465
456
462
471
467
498
514
526
548
589
491
507
467
469
483
478
477
485
475
441
462
481
474
491
470
486
459
492
517
504
465
472
473
469
500
502
452
462
484
454
499
492
518
496
469
511
548
568
562
549
525
517
515
528
493
525
492
489
450
464
467
459
459
427
415
452
467
467
509
541
619
686
745
736
675
620
557
594
630
645
686
688
622
605
544
580
520
454
464
397
362
288
238
203
139
89
47
35
14
29.504
C 1s/18
Not Specified
2017
12
11
14
10
8
0
9
Casa Info Follows
1
Calib M = 284.186 A = 284.5 BE ADD
0
0
0
   XPS     Spectrum    Lens Mode:Hybrid   Resolution:Pass energy 20    Iris(Aper):slot(Slot)
   Acqn. Time(s): 261        Sweeps: 4        Anode:Mono(Al (Mono))(150 W)   Step(meV): 100.0
   Dwell Time(ms): 250        Charge Neutraliser :On   Acquired On :17/12/11 14:10:08
XPS
14
1
0
Mono(Al (Mono))
1486.69
150
1e+037
1e+037
6000
6000
1e+037
1e+037
FAT
20
1e+037
-4.803
0
1e+037
1e+037
1e+037
1e+037
C
1s
-1
Kinetic Energy
eV
1186.69
0.1
2
Intensity
d
Transmission
d
pulse counting
0.25
4
0
1e+037
1e+037
1e+037
0
522
139
25341
1.1574
1.16426
1137
1.16426
1083
1.16422
1091
1.16418
1103
1.16414
1092
1.1641
1051
1.16406
1094
1.16402
1132
1.16398
1076
1.16393
1044
1.16389
1077
1.16385
1061
1.16381
1086
1.16377
1077
1.16373
1061
1.16369
1050
1.16365
1040
1.16361
1022
1.16357
1068
1.16352
1031
1.16348
1044
1.16344
1047
1.1634
970
1.16336
1041
1.16332
1039
1.16328
1000
1.16324
1042
1.1632
1042
1.16315
1001
1.16311
986
1.16307
982
1.16303
998
1.16299
1018
1.16295
1069
1.16292
1001
1.1629
1003
1.16287
1076
1.16285
1017
1.16282
990
1.1628
1048
1.16278
1039
1.16275
1099
1.16273
1022
1.1627
1052
1.16268
1043
1.16265
1022
1.16263
1038
1.16261
1048
1.16258
1083
1.16256
1021
1.16253
1080
1.16251
1081
1.16248
1080
1.16246
1082
1.16244
1091
1.16241
1116
1.16239
1162
1.16236
1141
1.16234
1135
1.16231
1137
1.16229
1191
1.16226
1113
1.16224
1131
1.16222
1166
1.16219
1205
1.16217
1158
1.16214
1205
1.16212
1219
1.16209
1177
1.16207
1231
1.16205
1264
1.16202
1231
1.162
1217
1.16197
1225
1.16195
1257
1.16192
1236
1.1619
1311
1.16188
1244
1.16185
1282
1.16183
1349
1.1618
1372
1.16178
1385
1.16175
1336
1.16173
1374
1.16171
1462
1.16168
1459
1.16166
1492
1.16163
1511
1.16161
1480
1.16158
1558
1.16156
1531
1.16153
1563
1.16151
1554
1.16149
1623
1.16146
1604
1.16144
1555
1.16141
1576
1.16139
1536
1.16136
1568
1.16134
1638
1.16132
1604
1.16129
1605
1.16127
1632
1.16124
1624
1.16122
1584
1.16119
1621
1.16117
1658
1.16115
1746
1.16112
1742
1.1611
1770
1.16107
1698
1.16105
1732
1.16102
1839
1.161
1804
1.16097
1881
1.16095
1949
1.16093
1878
1.1609
1985
1.16088
1904
1.16085
1980
1.16083
2003
1.1608
1950
1.16078
1934
1.16076
1972
1.16073
2079
1.16071
2046
1.16068
2203
1.16066
2300
1.16063
2420
1.16061
2568
1.16059
2706
1.16056
2819
1.16054
3081
1.16051
3251
1.16049
3388
1.16046
3470
1.16044
3516
1.16042
3652
1.16039
3651
1.16037
3639
1.16034
3654
1.16032
3628
1.16029
3748
1.16027
3694
1.16024
3849
1.16022
4020
1.1602
4237
1.16017
4523
1.16015
4750
1.16012
5260
1.1601
5912
1.16007
6833
1.16005
8010
1.16003
9802
1.16
12196
1.15998
15325
1.15995
19395
1.15993
23329
1.1599
25341
1.15988
24564
1.15986
21153
1.15983
16410
1.15981
12365
1.15978
8877
1.15976
6143
1.15973
3997
1.15971
2589
1.15969
1782
1.15966
1226
1.15964
927
1.15961
753
1.15959
615
1.15956
501
1.15954
444
1.15951
386
1.15949
374
1.15947
358
1.15944
320
1.15942
287
1.15939
278
1.15937
257
1.15934
264
1.15932
283
1.1593
268
1.15927
244
1.15925
260
1.15922
243
1.1592
230
1.15917
234
1.15915
209
1.15913
243
1.1591
209
1.15908
221
1.15905
198
1.15903
193
1.159
197
1.15898
189
1.15895
173
1.15893
196
1.15891
214
1.15888
203
1.15886
193
1.15883
166
1.15881
192
1.15878
194
1.15876
178
1.15874
187
1.15871
174
1.15869
196
1.15866
187
1.15864
190
1.15861
181
1.15859
189
1.15857
191
1.15854
166
1.15852
177
1.15849
151
1.15847
193
1.15844
199
1.15842
172
1.1584
172
1.15837
173
1.15835
175
1.15832
173
1.1583
181
1.15827
164
1.15825
180
1.15822
179
1.1582
179
1.15818
164
1.15815
181
1.15813
199
1.1581
139
1.15808
176
1.15805
175
1.15803
164
1.15801
157
1.15798
169
1.15796
167
1.15793
166
1.15791
194
1.15788
177
1.15786
157
1.15784
169
1.15781
167
1.15779
181
1.15776
158
1.15774
177
1.15771
173
1.15769
183
1.15767
152
1.15764
156
1.15762
179
1.15759
177
1.15757
169
1.15754
170
1.15752
151
1.15749
175
1.15747
173
1.15745
179
1.15742
158
1.1574
N 1s/19
Not Specified
2017
12
11
14
10
8
0
9
Casa Info Follows
1
Calib M = 284.186 A = 284.5 BE ADD
0
0
0
   XPS     Spectrum    Lens Mode:Hybrid   Resolution:Pass energy 20    Iris(Aper):slot(Slot)
   Acqn. Time(s): 241        Sweeps: 4        Anode:Mono(Al (Mono))(150 W)   Step(meV): 100.0
   Dwell Time(ms): 298        Charge Neutraliser :On   Acquired On :17/12/11 14:10:08
XPS
14
1
0
Mono(Al (Mono))
1486.69
150
1e+037
1e+037
6000
6000
1e+037
1e+037
FAT
20
1e+037
-4.803
0
1e+037
1e+037
1e+037
1e+037
N
1s
-1
Kinetic Energy
eV
1076.69
0.1
2
Intensity
d
Transmission
d
pulse counting
0.2985
4
0
1e+037
1e+037
1e+037
0
404
1989
2324
1.20216
1.21679
2134
1.21679
2031
1.21671
2008
1.21664
2049
1.21657
2057
1.2165
2052
1.21642
2068
1.21635
2050
1.21628
2078
1.21621
2054
1.21613
2077
1.21606
2086
1.21599
2073
1.21591
2029
1.21584
2048
1.21577
2050
1.2157
2019
1.21562
2049
1.21555
2041
1.21548
2045
1.2154
2089
1.21533
2029
1.21526
2081
1.21519
2090
1.21511
2089
1.21504
2072
1.21497
2081
1.2149
2139
1.21482
2121
1.21475
1998
1.21468
2035
1.2146
2055
1.21453
2173
1.21446
2173
1.21439
2082
1.21431
2072
1.21424
2051
1.21417
1989
1.2141
2072
1.21402
2100
1.21395
2158
1.21388
2083
1.2138
2045
1.21373
2046
1.21366
2031
1.21359
2133
1.21351
2135
1.21344
2072
1.21337
2069
1.21329
2075
1.21322
2090
1.21315
2075
1.21308
2124
1.213
2073
1.21293
2100
1.21286
2133
1.21279
2110
1.21271
2079
1.21264
2065
1.21257
2092
1.21249
2087
1.21242
2057
1.21235
2049
1.21228
2116
1.2122
2082
1.21213
2034
1.21206
2090
1.21198
2087
1.21191
2113
1.21184
2069
1.21177
2095
1.21169
2062
1.21162
2045
1.21155
2097
1.21148
2104
1.2114
2139
1.21133
2137
1.21126
2169
1.21118
2140
1.21111
2140
1.21104
2152
1.21097
2172
1.21089
2237
1.21082
2198
1.21075
2266
1.21068
2324
1.2106
2270
1.21053
2287
1.21046
2221
1.21038
2292
1.21031
2255
1.21024
2234
1.21017
2295
1.21009
2231
1.21002
2212
1.20995
2288
1.20987
2210
1.2098
2230
1.20973
2247
1.20966
2222
1.20958
2158
1.20951
2133
1.20944
2192
1.20937
2140
1.20929
2189
1.20922
2207
1.20915
2186
1.20907
2143
1.209
2181
1.20893
2154
1.20886
2191
1.20878
2134
1.20871
2195
1.20864
2200
1.20856
2174
1.20849
2141
1.20842
2117
1.20835
2148
1.20827
2133
1.2082
2055
1.20813
2063
1.20806
2145
1.20798
2057
1.20791
2035
1.20784
2001
1.20776
2088
1.20769
2097
1.20762
2076
1.20755
2095
1.20747
2107
1.2074
2016
1.20733
2019
1.20726
2088
1.20718
2106
1.20711
2071
1.20704
2084
1.20696
2057
1.20689
2119
1.20682
2115
1.20675
2056
1.20667
2115
1.2066
2074
1.20653
2029
1.20645
2072
1.20638
2036
1.20631
2072
1.20624
2038
1.20616
2073
1.20609
2058
1.20602
2133
1.20595
2137
1.20587
2046
1.2058
2053
1.20573
2091
1.20565
2040
1.20558
2031
1.20551
2069
1.20544
2074
1.20536
2066
1.20529
2047
1.20522
2078
1.20514
2027
1.20507
2052
1.205
2098
1.20493
2081
1.20485
2012
1.20478
2125
1.20471
2057
1.20464
2045
1.20456
2080
1.20449
2074
1.20442
2121
1.20434
2114
1.20427
2113
1.2042
2139
1.20413
2050
1.20405
2067
1.20398
2071
1.20391
2085
1.20384
2095
1.20376
2093
1.20369
2134
1.20362
2097
1.20354
2065
1.20347
2072
1.2034
2104
1.20333
2071
1.20325
2090
1.20318
2068
1.20311
2107
1.20303
2141
1.20296
2071
1.20289
2101
1.20282
2111
1.20274
2062
1.20267
2081
1.2026
2101
1.20253
2058
1.20245
2124
1.20238
2057
1.20231
2118
1.20223
2214
1.20216
end of experiment