File: data/raw_data/xps/20170920_Gr-NH2_for_Radisurf/GrNH2.vms
VAMAS Surface Chemical Analysis Standard Data Transfer Format 1988 May 4
Not Specified
Kratos Axis
Not Specified
/C=/data/Monica/Gruppe105/Emil/170921/GrNH2.dset
0
MAP
REGULAR
1
2
32768
32768
1
Etch Time
s
0
0
0
0
2
Survey/2
Not Specified
2017
9
21
19
58
30
0
3
   XPS     Spectrum    Lens Mode:Hybrid   Resolution:Pass energy 160   Iris(Aper):slot(Slot)
   Acqn. Time(s): 540        Sweeps: 2        Anode:Mono(Al (Mono))(150 W)   Step(meV): 500.0
   Dwell Time(ms): 100        Charge Neutraliser :On   Acquired On :17/09/21 19:58:30
XPS
96.316
2.754
0
Mono(Al (Mono))
1486.69
150
1E+37
1E+37
6000
6000
1E+37
1E+37
FAT
160
1E+37
-4.803
0
1E+37
1E+37
1E+37
1E+37
Wide
None
-1
Kinetic Energy
eV
136.69
0.5
2
Intensity
d
Transmission
d
pulse counting
0.1
1E+37
33
10238
10249
10075
10151
10160
10202
10055
9949
10117
10150
10192
10054
10045
10190
10124
10239
10136
10141
10174
10029
10151
10185
10080
10055
10212
10045
10252
10154
9930
10240
10289
10243
10093
10192
10208
10156
10204
10165
10265
10193
10329
10382
10327
10359
10555
10827
10834
10644
10586
10675
10671
10633
10472
10571
10479
10703
10696
10660
10651
10740
10851
10639
10718
10862
10957
10885
10932
10952
10821
11070
10871
11053
11124
10938
11010
11216
11101
11122
11155
11314
11242
11311
11322
11397
11496
11548
11524
11412
11585
11534
11627
11547
11708
11616
11633
11832
11805
11893
11981
12050
12008
12078
12312
12282
12338
12398
12400
12512
12304
12442
12486
12409
12586
12419
12353
12529
12625
12942
13031
13365
13420
13673
13751
13648
13751
13815
13619
13806
13557
13252
12886
12912
12516
12034
11888
11595
11015
10466
10252
9885
9564
9242
9078
8782
8621
8444
8378
8401
8207
8205
8239
8300
8126
8305
8381
8260
8390
8447
8316
8408
8250
8438
8290
8142
8383
8365
8315
8434
8458
8453
8383
8542
8547
8716
8581
8604
8526
8663
8602
8598
8554
8498
8574
8697
8596
8818
8745
8622
8761
8838
8644
8614
8924
8755
8823
8804
8846
8848
8831
8925
8932
9067
8994
8873
8951
8895
8981
9011
9164
9034
9060
9092
9008
9137
9163
9089
9132
9157
9326
9371
9243
9316
9402
9302
9238
9273
9346
9258
9369
9541
9314
9385
9397
9377
9377
9635
9489
9458
9511
9599
9544
9556
9519
9660
9701
9777
9451
9536
9748
9577
9658
9802
9786
9609
9767
9635
9664
9664
9784
9739
9858
9778
9734
9859
9764
9813
10008
9961
9916
10088
9927
9900
10091
9991
10092
10049
10099
10083
10113
10189
10179
10170
10082
10272
10220
10295
10354
10281
10387
10326
10374
10477
10652
10382
10493
10516
10540
10388
10611
10468
10448
10513
10618
10538
10668
10800
10879
10727
10816
10650
10721
10860
10830
10828
10868
10847
10682
10848
11087
10949
10997
11014
11121
11020
11078
11149
11303
11439
11393
11285
11191
11485
11469
11380
11447
11422
11457
11432
11397
11606
11467
11452
11584
11644
11900
12051
11992
12170
12267
12483
12461
12478
12345
12268
12084
12062
11668
11661
11722
11428
11287
11264
11268
11122
11186
11388
11468
11764
11986
12529
12844
13395
13379
13821
13602
13352
13053
12529
12272
11784
11384
10697
10167
9805
9096
8735
8376
8284
8450
8054
8102
8053
8186
8178
7966
8079
8131
8061
8149
8108
8001
8084
8025
8110
8129
8123
8139
8194
8014
8196
7947
8344
8299
8129
8217
8231
8289
8203
8381
8237
8214
8315
8234
8301
8232
8261
8352
8334
8384
8237
8505
8430
8440
8277
8460
8375
8498
8447
8423
8471
8416
8435
8466
8503
8239
8395
8578
8639
8562
8529
8524
8403
8526
8519
8579
8684
8560
8684
8497
8596
8668
8690
8615
8583
8688
8714
8707
8689
8800
8714
8774
8868
8869
8742
8734
8774
8836
8748
8756
8667
8766
8734
8729
8890
8848
9042
8905
9054
8883
8934
9009
8977
8903
8950
9125
8940
9092
8962
8966
9041
8918
9026
8935
9023
8948
8971
9132
9123
9008
9170
9241
9086
9180
9056
9160
9214
9165
9189
9206
9125
9134
9172
8994
9195
9026
9329
9307
9142
9163
9298
9290
9242
9201
9237
9397
9363
9378
9399
9351
9398
9433
9530
9580
9470
9468
9436
9408
9594
9511
9524
9469
9369
9553
9695
9480
9619
9615
9604
9721
9584
9691
9565
9622
9678
9687
9556
9658
9856
9652
9670
9718
9827
9761
9880
9924
9732
9671
9853
9875
9797
9853
9840
9930
9743
9948
9806
9867
9859
9900
10032
9887
10067
10027
10028
9896
10051
9953
10007
9968
10079
10063
10155
10166
9964
10069
10016
10202
10237
10208
10190
10234
10009
10232
10322
10151
10015
10240
10167
10184
10116
10132
10281
10320
10324
10328
10146
10335
10245
10461
10282
10430
10503
10291
10372
10286
10580
10382
10563
10540
10429
10424
10288
10558
10505
10403
10397
10640
10573
10576
10643
10462
10373
10569
10413
10666
10536
10460
10588
10403
10572
10563
10683
10721
10584
10672
10654
10746
10963
10626
10541
10654
10745
10758
10709
10932
10842
10690
10860
10814
10667
10873
11007
11003
10880
10886
10711
11004
10977
10998
10942
11099
10884
10795
11021
11089
11062
11136
11072
11091
11170
11092
11060
11019
10966
11176
11075
11299
11308
11305
11274
11134
11308
11183
11275
11177
11111
11217
11339
11174
11428
11290
11402
11421
11271
11571
11628
11437
11701
11405
11370
11386
11364
11553
11415
11476
11652
11448
11483
11661
11473
11696
11661
11546
11522
11557
11712
11817
11679
11684
11723
11736
11927
11767
11880
11762
11759
11983
11696
11951
11832
11756
11982
11983
12067
11984
11916
12008
12147
11986
12019
11975
12072
12003
11951
12067
11982
11982
12112
11966
11955
11993
12022
11885
12025
12193
12167
12181
12252
12222
12666
12481
12798
12904
12936
12979
12822
12673
12379
12116
11820
11718
11471
11315
11014
10787
10544
10210
9941
9549
9533
9581
9733
9927
10295
11059
13944
21076
33680
37517
25170
13588
9150
8227
8006
7895
7860
7774
7648
7735
7651
7675
7771
7854
7619
7648
7770
7799
7685
7756
7799
7727
7755
7761
7868
7869
7798
7927
7860
7666
7722
7818
7952
7987
7841
8137
8037
7999
7879
7718
7945
7731
7940
7878
7993
7966
7891
7940
7936
8006
8012
7940
8158
7942
7787
8055
8090
8138
8040
7961
7971
7977
8095
8016
8140
8164
8146
8220
8166
8037
8143
8218
8245
8256
8083
8129
8250
8228
8326
8209
8384
8330
8280
8330
8308
8346
8265
8371
8358
8531
8484
8593
8562
8420
8433
8498
8356
8544
8678
8535
8428
8325
8374
8499
8549
8502
8624
8602
8509
8617
8529
8626
8573
8480
8423
8415
8644
8571
8495
8518
8583
8582
8682
8643
8848
8672
8745
8951
8974
9331
9364
9428
9304
8804
8766
8606
8764
8749
8718
8724
8704
8761
8839
8835
8684
8782
8869
8717
8935
8828
8830
8872
8851
8796
8886
8988
8910
9116
9010
9162
8993
8929
9089
9096
9143
9112
9099
9132
9036
9161
9207
9117
9110
9159
9250
9249
9412
9295
9359
9566
9524
9582
9589
9656
9753
9529
9540
9552
9423
9536
9455
9449
9277
9567
9466
9339
9226
9331
9233
9227
9365
9301
9267
9231
9272
9382
9622
9481
9804
9740
9920
9913
10091
10242
10036
10131
10468
10473
10416
10390
10427
10315
10209
10162
9714
9207
8604
8064
7710
7062
6692
6344
5885
5712
5303
5173
5148
5420
5400
5886
6797
8148
10234
13704
22021
29814
40141
41218
16809
3066
1682
1369
1139
1044
989
977
947
931
992
999
1017
996
981
906
913
898
930
872
838
843
875
915
883
885
861
898
862
836
880
856
836
860
920
898
858
892
853
883
867
864
847
840
898
831
908
874
909
1013
1024
1115
1086
968
952
866
887
888
895
892
851
812
854
851
800
830
862
845
853
813
822
871
828
786
837
785
806
816
877
822
854
904
1024
1084
1066
905
928
832
805
828
840
790
816
796
833
813
796
851
853
779
780
791
794
800
804
789
808
820
766
790
814
834
916
1023
1222
1255
1024
815
776
726
755
739
735
798
787
825
945
959
1087
1214
1185
1050
897
826
717
756
741
708
753
741
737
780
734
742
735
700
757
723
704
789
746
771
749
727
749
744
753
766
761
760
762
717
799
726
779
777
755
763
735
757
768
706
706
737
755
754
737
821
960
1033
1131
1132
975
815
722
714
729
745
774
715
744
769
785
766
754
693
739
726
705
740
730
720
722
737
729
730
725
712
681
745
750
729
720
754
718
734
723
779
730
700
751
706
756
762
768
752
800
783
775
787
796
809
826
783
810
788
807
789
771
781
747
750
705
713
662
691
697
662
664
642
671
716
757
847
936
1068
1214
1256
1187
1005
796
720
761
864
934
901
878
869
810
771
730
704
645
611
550
497
452
416
352
243
156
82
44
33
29.504
Survey/5
Not Specified
2017
9
21
20
10
22
0
3
   XPS     Spectrum    Lens Mode:Hybrid   Resolution:Pass energy 160   Iris(Aper):slot(Slot)
   Acqn. Time(s): 540        Sweeps: 2        Anode:Mono(Al (Mono))(150 W)   Step(meV): 500.0
   Dwell Time(ms): 100        Charge Neutraliser :On   Acquired On :17/09/21 20:10:22
XPS
95.124
1.613
0
Mono(Al (Mono))
1486.69
150
1E+37
1E+37
6000
6000
1E+37
1E+37
FAT
160
1E+37
-4.803
0
1E+37
1E+37
1E+37
1E+37
Wide
None
-1
Kinetic Energy
eV
136.69
0.5
2
Intensity
d
Transmission
d
pulse counting
0.1
1E+37
102
11808
11748
11849
11739
11738
11987
11768
11684
11614
11625
11875
11725
11850
11823
11734
11746
11820
11855
11886
11848
11864
11950
11902
11646
11747
11907
11882
11903
11879
12015
12061
12135
12035
11932
11908
11986
11801
11996
11797
12029
11909
11879
11983
12391
12384
12655
12917
12843
12688
12543
12401
12308
12328
12255
12269
12318
12528
12444
12442
12322
12473
12513
12531
12531
12674
12776
12670
12763
12702
12801
12836
12907
12895
13044
12885
12848
13000
13014
13161
13155
13134
13175
13096
13298
13379
13306
13275
13488
13358
13535
13421
13556
13682
13753
13662
13664
13649
13842
13971
14221
14002
14202
14311
14488
14486
14628
14569
14365
14622
14451
14508
14645
14440
14568
14497
14544
14739
14885
15109
15411
15731
15672
15916
15776
16035
15976
16028
15914
15801
15663
15321
15127
14699
14415
14312
13702
13482
12993
12608
12451
12301
11830
11752
11489
11287
11195
11314
11039
11101
11039
11045
11198
11166
11256
11234
11401
11210
11184
11389
11209
11182
11358
11333
11411
11301
11436
11433
11161
11455
11408
11678
11501
11728
11541
11558
11394
11697
11780
11711
11628
11680
11763
11770
11974
11732
11796
11934
11988
12031
12033
11718
12039
12054
12137
12129
12089
12058
12056
12227
12260
12081
12228
12357
12319
12559
12259
12573
12348
12618
12468
12407
12609
12489
12493
12456
12569
12785
12704
12622
12598
12693
12819
12730
12847
12795
12843
13022
12839
12810
12902
12934
13104
13118
13021
13000
13026
13132
13341
13016
13145
13351
13281
13441
13289
13437
13569
13355
13520
13384
13499
13528
13703
13379
13782
13661
13647
13460
13518
13702
13791
13776
13616
14040
13858
13774
13753
13881
14080
13873
13853
13952
13903
13929
14067
14131
14104
14226
14252
14257
14243
14403
14380
14235
13938
14075
14425
14298
14369
14445
14538
14384
14551
14660
14502
14467
14626
14440
14592
14676
14841
14723
14899
14876
14819
14983
15090
15132
15053
15211
15152
15088
15003
15323
15289
15087
15109
15314
15244
15168
15338
15477
15329
15244
15489
15455
15613
15574
15881
15845
15899
15925
16058
15661
15821
15723
15885
15981
16054
15791
15843
15831
16158
15847
16183
15988
16185
16466
16587
16836
16819
16732
16833
16687
16820
16525
16434
16199
16042
15999
15682
15410
15564
15415
15272
15453
15339
15848
15788
16485
16990
17220
17472
17837
17790
17861
17615
17215
16848
16712
16202
15531
14914
14442
13821
13506
12986
12918
12710
12702
12644
12582
12571
12625
12337
12471
12448
12516
12422
12487
12519
12357
12369
12452
12505
12347
12446
12482
12538
12354
12640
12574
12520
12536
12541
12607
12591
12607
12566
12695
12482
12659
12495
12572
12413
12569
12655
12609
12426
12608
12739
12397
12504
12649
12646
12848
12633
12508
12595
12460
12582
12587
12682
12654
12747
12453
12733
12641
12537
12559
12645
12727
12560
12676
12810
12807
12753
12743
12792
12719
12703
12707
12637
12571
12400
12424
12522
12624
12467
12560
12396
12512
12393
12523
12446
12687
12358
12504
12679
12416
12416
12347
12373
12466
12478
12405
12374
12444
12301
12539
12469
12589
12576
12411
12406
12433
12560
12596
12537
12463
12484
12281
12371
12384
12488
12392
12361
12414
12268
12318
12443
12298
12420
12282
12240
12494
12219
12193
12331
12052
11899
12172
12020
12047
12175
12326
12006
12147
12057
12076
11985
11985
12077
12078
12084
12205
12144
12135
12240
12207
12185
12201
12256
12219
12140
12059
12122
12114
12258
12041
12276
12244
12169
12032
12356
12264
12264
12253
12205
12205
12164
12354
12360
12448
12357
12404
12348
12367
12430
12365
12318
12457
12258
12413
12296
12217
12184
12218
12269
12256
12340
12196
12214
12171
12286
12183
12183
12220
11989
12148
12082
12081
12119
12212
12187
12330
12169
12243
12074
12332
12164
12327
12290
12153
12218
12228
12362
12293
12339
12310
12350
12132
12126
12377
12236
12159
12317
12321
12260
12292
12242
12275
12182
12351
12593
12338
12588
12306
12328
12000
12138
12263
12049
12112
11943
11924
12170
12220
12310
12622
12521
12339
11911
11658
11738
11564
11387
11519
11401
11312
11422
11354
11303
11363
11328
11350
11557
11448
11524
11490
11331
11395
11379
11432
11529
11293
11354
11467
11392
11397
11433
11383
11372
11600
11514
11450
11664
11507
11554
11612
11745
11629
11561
11582
11657
11472
11699
11569
11612
11658
11593
11746
11610
11694
11613
11763
11714
11665
11532
11821
11672
11824
11641
11821
11929
11953
11866
11783
11866
11890
11795
12038
11966
11876
11975
11657
11894
12031
11879
11835
11878
11842
11919
11807
11980
11638
11952
12075
12085
12095
11958
12040
11874
12029
12053
11836
11983
12068
11988
12257
12070
12022
12158
12187
12112
12041
12114
12193
12208
12046
12329
12093
12092
12191
12230
12313
12155
12191
12395
12196
12465
12207
12408
12474
12529
12540
12677
12288
12219
12235
12290
12322
12399
12521
12857
12806
12534
12244
12037
11862
11962
11968
12072
12078
11998
12118
11969
12066
12219
12235
12530
12592
12915
12888
13169
12862
12821
12697
12409
12044
12068
11798
11476
11207
10897
10890
10369
10113
9908
9670
9674
9474
9486
9655
10034
10971
14059
21173
32532
36176
25717
15221
10096
8285
7786
7611
7621
7532
7467
7574
7493
7491
7472
7564
7485
7418
7500
7532
7615
7762
7573
7500
7468
7483
7520
7618
7613
7477
7565
7555
7682
7612
7664
7838
7728
7649
7741
7693
7739
7680
7684
7747
7710
7727
7828
7921
7669
7757
7570
7808
7817
7725
7878
7622
7811
7813
7901
7853
7896
7806
7739
7947
7902
7821
7722
7776
7984
8100
8061
7964
8015
8060
8126
8134
8009
8032
8150
8097
7868
8058
8059
7999
8030
7980
8178
8168
8070
8180
8212
8256
8342
8408
8423
8333
8159
8205
8163
8268
8070
8260
8130
8274
8339
8414
8225
8201
8345
8004
8433
8334
8340
8268
8337
8147
8207
8234
8340
8418
8445
8334
8338
8456
8255
8504
8446
8525
8604
8562
8721
8763
9046
9094
9131
8797
8517
8538
8542
8512
8441
8552
8564
8701
8564
8571
8851
8628
8769
8713
8710
8737
8567
8760
8776
8869
8694
8823
8756
8841
8780
8737
8947
8904
8817
8868
8944
8856
8927
8906
8901
8834
8829
8936
9171
8980
9075
9008
9129
9235
9487
9623
9595
9507
9689
10096
9909
9382
9288
9082
9219
9253
9125
9428
9349
9329
9125
9161
8999
9250
9110
9041
9186
9164
9106
9227
9182
9119
9295
9425
9388
9546
9640
9675
9790
9963
9947
9992
10138
10081
10367
10068
10222
10290
10364
10455
10302
9680
8952
8173
7752
7425
6971
6529
6153
5834
5616
5445
5510
5595
5658
6092
6866
8435
10556
13453
21262
29403
37916
36168
15827
3681
2358
2110
1855
1847
1709
1755
1765
1760
1721
1757
1842
1837
1810
1730
1766
1773
1698
1721
1715
1703
1741
1678
1727
1723
1741
1760
1706
1681
1685
1680
1705
1698
1711
1710
1659
1703
1716
1782
1758
1720
1710
1701
1751
1672
1706
1713
1744
1878
1956
1930
1996
1771
1741
1783
1711
1740
1692
1728
1702
1756
1709
1727
1718
1705
1639
1731
1686
1720
1673
1714
1723
1707
1659
1644
1682
1671
1674
1620
1657
1805
1886
1976
1914
1815
1792
1761
1709
1707
1685
1782
1806
1732
1794
1685
1670
1716
1684
1742
1672
1680
1672
1665
1721
1670
1692
1637
1707
1677
1715
1670
1797
1875
2099
2164
1910
1711
1616
1617
1611
1639
1602
1665
1610
1701
1733
1884
2002
2071
2055
1965
1752
1622
1598
1595
1637
1613
1599
1547
1612
1625
1615
1555
1640
1675
1681
1593
1654
1699
1687
1671
1651
1652
1601
1573
1673
1588
1682
1593
1657
1557
1610
1596
1638
1598
1504
1564
1524
1599
1591
1537
1534
1497
1566
1527
1574
1590
1732
1911
1983
1879
1756
1653
1472
1492
1486
1494
1532
1571
1526
1601
1617
1629
1465
1485
1411
1391
1341
1365
1317
1302
1318
1363
1392
1417
1324
1423
1439
1290
1327
1371
1315
1300
1353
1332
1364
1412
1277
1215
1178
1200
1218
1180
1181
1204
1309
1390
1348
1319
1271
1220
1083
1050
1017
979
1047
1048
1130
1126
1076
999
884
873
759
780
788
752
742
736
745
818
811
951
1027
1166
1318
1450
1360
1208
959
900
839
865
910
955
935
909
876
813
781
727
678
643
650
592
536
550
446
381
287
233
161
102
29.504
end of experiment